Workbook
Name alert_threshold: Настройки!$B$8
Name fact_months: Настройки!$B$7

Sheet Настройки
A1: Настройки модели
A2: План-факт ФОТ. Данные смоделированы, это иллюстрация метода. Comp Budget Lab.
A4: Менять можно только зелёные ячейки. Всё остальное пересчитается само.
A6: Имя | B6: Значение | C6: Что это | D6: Пояснение
A7: fact_months | B7: 8 | C7: Месяцев с фактом | D7: Месяцы нумеруются с января: 8 значит, что факт есть по август включительно. Остальные месяцы — прогноз.
A8: alert_threshold | B8: 0.03 | C8: Порог сигнала | D8: Если ожидание на год выше плана на этот процент или больше, на листе «Итоги» загорается «проблема».
A11: Что в плане
A12: План — ФОТ подразделения: оклады и переменная часть, без страховых взносов работодателя. Годовая сумма разложена по месяцам с учётом сезонности отпусков. Прогноз на оставшиеся месяцы продолжает тренд каждого подразделения: кто восемь месяцев шёл выше плана, тот и дальше идёт выше.

Sheet Тренд
A1: Тренд подразделений
A2: На сколько процентов подразделение шло выше (или ниже) плана в месяцы с фактом. Прогноз на оставшиеся месяцы — план, умноженный на (1 + тренд). Это исходные данные: поменяйте тренд, и прогноз с итогами пересчитаются.
A5: Подразделение | B5: Тренд, %
A6: Разработка | B6: 2.9725152
A7: Продажи | B7: 9.5584811
A8: Операции | B8: 2.7245624
A9: Производство | B9: 2.9373962
A10: Маркетинг | B10: 2.5782464
A11: Поддержка клиентов | B11: 2.2121372
A12: Юристы | B12: -1.2496258

Sheet Данные
A1: План и факт по подразделениям и месяцам
A2: Жёлтое — из CSV. Голубое — считается здесь. Отклонение — факт (или прогноз) минус план: плюс значит перерасход.
A4: Подразделение | B4: Месяц | C4: № | D4: План, ₽ | E4: Факт, ₽ | F4: Прогноз, ₽ | G4: Ожидание, ₽ | H4: Отклонение, ₽ | I4: Отклонение, % | J4: Накопительно, ₽
A5: Разработка | B5: янв | C5: 1 | D5: 10940749 | E5: 11254212 | F5: =IF(C5<=fact_months,"",ROUND(D5*(1+Тренд!$B$6/100),2)) | G5: =IF(C5<=fact_months,E5,F5) -> 11254212 | H5: =G5-D5 -> 313463.6 | I5: =IF(D5=0,"",H5/D5) -> 0.028651019 | J5: =H5 -> 313463.6
A6: Разработка | B6: фев | C6: 2 | D6: 10909128 | E6: 11225642 | F6: =IF(C6<=fact_months,"",ROUND(D6*(1+Тренд!$B$6/100),2)) | G6: =IF(C6<=fact_months,E6,F6) -> 11225642 | H6: =G6-D6 -> 316514.33 | I6: =IF(D6=0,"",H6/D6) -> 0.029013715 | J6: =J5+H6 -> 629977.93
A7: Разработка | B7: мар | C7: 3 | D7: 10772105 | E7: 11090995 | F7: =IF(C7<=fact_months,"",ROUND(D7*(1+Тренд!$B$6/100),2)) | G7: =IF(C7<=fact_months,E7,F7) -> 11090995 | H7: =G7-D7 -> 318889.57 | I7: =IF(D7=0,"",H7/D7) -> 0.029603273 | J7: =J6+H7 -> 948867.5
A8: Разработка | B8: апр | C8: 4 | D8: 10592922 | E8: 10899319 | F8: =IF(C8<=fact_months,"",ROUND(D8*(1+Тренд!$B$6/100),2)) | G8: =IF(C8<=fact_months,E8,F8) -> 10899319 | H8: =G8-D8 -> 306397.62 | I8: =IF(D8=0,"",H8/D8) -> 0.028924751 | J8: =J7+H8 -> 1255265.1
A9: Разработка | B9: май | C9: 5 | D9: 10392657 | E9: 10711795 | F9: =IF(C9<=fact_months,"",ROUND(D9*(1+Тренд!$B$6/100),2)) | G9: =IF(C9<=fact_months,E9,F9) -> 10711795 | H9: =G9-D9 -> 319137.47 | I9: =IF(D9=0,"",H9/D9) -> 0.030707976 | J9: =J8+H9 -> 1574402.6
A10: Разработка | B10: июн | C10: 6 | D10: 10202933 | E10: 10508815 | F10: =IF(C10<=fact_months,"",ROUND(D10*(1+Тренд!$B$6/100),2)) | G10: =IF(C10<=fact_months,E10,F10) -> 10508815 | H10: =G10-D10 -> 305881.82 | I10: =IF(D10=0,"",H10/D10) -> 0.029979792 | J10: =J9+H10 -> 1880284.4
A11: Разработка | B11: июл | C11: 7 | D11: 10139692 | E11: 10449516 | F11: =IF(C11<=fact_months,"",ROUND(D11*(1+Тренд!$B$6/100),2)) | G11: =IF(C11<=fact_months,E11,F11) -> 10449516 | H11: =G11-D11 -> 309823.69 | I11: =IF(D11=0,"",H11/D11) -> 0.030555533 | J11: =J10+H11 -> 2190108.1
A12: Разработка | B12: авг | C12: 8 | D12: 10160772 | E12: 10471195 | F12: =IF(C12<=fact_months,"",ROUND(D12*(1+Тренд!$B$6/100),2)) | G12: =IF(C12<=fact_months,E12,F12) -> 10471195 | H12: =G12-D12 -> 310422.08 | I12: =IF(D12=0,"",H12/D12) -> 0.030551031 | J12: =J11+H12 -> 2500530.2
A13: Разработка | B13: сен | C13: 9 | D13: 10382117 | F13: =IF(C13<=fact_months,"",ROUND(D13*(1+Тренд!$B$6/100),2)) -> 10690727 | G13: =IF(C13<=fact_months,E13,F13) -> 10690727 | H13: =G13-D13 -> 308610.01 | I13: =IF(D13=0,"",H13/D13) -> 0.029725152 | J13: =J12+H13 -> 2809140.2
A14: Разработка | B14: окт | C14: 10 | D14: 10603462 | F14: =IF(C14<=fact_months,"",ROUND(D14*(1+Тренд!$B$6/100),2)) -> 10918651 | G14: =IF(C14<=fact_months,E14,F14) -> 10918651 | H14: =G14-D14 -> 315189.52 | I14: =IF(D14=0,"",H14/D14) -> 0.029725153 | J14: =J13+H14 -> 3124329.7
A15: Разработка | B15: ноя | C15: 11 | D15: 10687784 | F15: =IF(C15<=fact_months,"",ROUND(D15*(1+Тренд!$B$6/100),2)) -> 11005480 | G15: =IF(C15<=fact_months,E15,F15) -> 11005480 | H15: =G15-D15 -> 317695.99 | I15: =IF(D15=0,"",H15/D15) -> 0.029725152 | J15: =J14+H15 -> 3442025.7
A16: Разработка | B16: дек | C16: 12 | D16: 10698324 | F16: =IF(C16<=fact_months,"",ROUND(D16*(1+Тренд!$B$6/100),2)) -> 11016333 | G16: =IF(C16<=fact_months,E16,F16) -> 11016333 | H16: =G16-D16 -> 318009.3 | I16: =IF(D16=0,"",H16/D16) -> 0.029725152 | J16: =J15+H16 -> 3760035
A17: Продажи | B17: янв | C17: 1 | D17: 7950800 | E17: 8699641.8 | F17: =IF(C17<=fact_months,"",ROUND(D17*(1+Тренд!$B$7/100),2)) | G17: =IF(C17<=fact_months,E17,F17) -> 8699641.8 | H17: =G17-D17 -> 748841.73 | I17: =IF(D17=0,"",H17/D17) -> 0.09418445 | J17: =H17 -> 748841.73
A18: Продажи | B18: фев | C18: 2 | D18: 7927820.8 | E18: 8693908.3 | F18: =IF(C18<=fact_months,"",ROUND(D18*(1+Тренд!$B$7/100),2)) | G18: =IF(C18<=fact_months,E18,F18) -> 8693908.3 | H18: =G18-D18 -> 766087.48 | I18: =IF(D18=0,"",H18/D18) -> 0.096632794 | J18: =J17+H18 -> 1514929.2
A19: Продажи | B19: мар | C19: 3 | D19: 7828244.3 | E19: 8569762.7 | F19: =IF(C19<=fact_months,"",ROUND(D19*(1+Тренд!$B$7/100),2)) | G19: =IF(C19<=fact_months,E19,F19) -> 8569762.7 | H19: =G19-D19 -> 741518.35 | I19: =IF(D19=0,"",H19/D19) -> 0.094723455 | J19: =J18+H19 -> 2256447.6
A20: Продажи | B20: апр | C20: 4 | D20: 7698028.9 | E20: 8431702 | F20: =IF(C20<=fact_months,"",ROUND(D20*(1+Тренд!$B$7/100),2)) | G20: =IF(C20<=fact_months,E20,F20) -> 8431702 | H20: =G20-D20 -> 733673.08 | I20: =IF(D20=0,"",H20/D20) -> 0.095306615 | J20: =J19+H20 -> 2990120.6
A21: Продажи | B21: май | C21: 5 | D21: 7552494 | E21: 8278567.5 | F21: =IF(C21<=fact_months,"",ROUND(D21*(1+Тренд!$B$7/100),2)) | G21: =IF(C21<=fact_months,E21,F21) -> 8278567.5 | H21: =G21-D21 -> 726073.44 | I21: =IF(D21=0,"",H21/D21) -> 0.09613691 | J21: =J20+H21 -> 3716194.1
A22: Продажи | B22: июн | C22: 6 | D22: 7414618.9 | E22: 8116761.9 | F22: =IF(C22<=fact_months,"",ROUND(D22*(1+Тренд!$B$7/100),2)) | G22: =IF(C22<=fact_months,E22,F22) -> 8116761.9 | H22: =G22-D22 -> 702142.96 | I22: =IF(D22=0,"",H22/D22) -> 0.094697107 | J22: =J21+H22 -> 4418337
A23: Продажи | B23: июл | C23: 7 | D23: 7368660.5 | E23: 8072192.1 | F23: =IF(C23<=fact_months,"",ROUND(D23*(1+Тренд!$B$7/100),2)) | G23: =IF(C23<=fact_months,E23,F23) -> 8072192.1 | H23: =G23-D23 -> 703531.54 | I23: =IF(D23=0,"",H23/D23) -> 0.095476178 | J23: =J22+H23 -> 5121868.6
A24: Продажи | B24: авг | C24: 8 | D24: 7383980 | E24: 8092200.6 | F24: =IF(C24<=fact_months,"",ROUND(D24*(1+Тренд!$B$7/100),2)) | G24: =IF(C24<=fact_months,E24,F24) -> 8092200.6 | H24: =G24-D24 -> 708220.66 | I24: =IF(D24=0,"",H24/D24) -> 0.095913134 | J24: =J23+H24 -> 5830089.2
A25: Продажи | B25: сен | C25: 9 | D25: 7544834.3 | F25: =IF(C25<=fact_months,"",ROUND(D25*(1+Тренд!$B$7/100),2)) -> 8266005.9 | G25: =IF(C25<=fact_months,E25,F25) -> 8266005.9 | H25: =G25-D25 -> 721171.56 | I25: =IF(D25=0,"",H25/D25) -> 0.095584811 | J25: =J24+H25 -> 6551260.8
A26: Продажи | B26: окт | C26: 10 | D26: 7705688.7 | F26: =IF(C26<=fact_months,"",ROUND(D26*(1+Тренд!$B$7/100),2)) -> 8442235.4 | G26: =IF(C26<=fact_months,E26,F26) -> 8442235.4 | H26: =G26-D26 -> 736546.79 | I26: =IF(D26=0,"",H26/D26) -> 0.095584811 | J26: =J25+H26 -> 7287807.6
A27: Продажи | B27: ноя | C27: 11 | D27: 7766966.5 | F27: =IF(C27<=fact_months,"",ROUND(D27*(1+Тренд!$B$7/100),2)) -> 8509370.5 | G27: =IF(C27<=fact_months,E27,F27) -> 8509370.5 | H27: =G27-D27 -> 742404.02 | I27: =IF(D27=0,"",H27/D27) -> 0.09558481 | J27: =J26+H27 -> 8030211.6
A28: Продажи | B28: дек | C28: 12 | D28: 7774626.2 | F28: =IF(C28<=fact_months,"",ROUND(D28*(1+Тренд!$B$7/100),2)) -> 8517762.4 | G28: =IF(C28<=fact_months,E28,F28) -> 8517762.4 | H28: =G28-D28 -> 743136.18 | I28: =IF(D28=0,"",H28/D28) -> 0.095584811 | J28: =J27+H28 -> 8773347.8
A29: Операции | B29: янв | C29: 1 | D29: 7018598.6 | E29: 7218075.4 | F29: =IF(C29<=fact_months,"",ROUND(D29*(1+Тренд!$B$8/100),2)) | G29: =IF(C29<=fact_months,E29,F29) -> 7218075.4 | H29: =G29-D29 -> 199476.77 | I29: =IF(D29=0,"",H29/D29) -> 0.028421168 | J29: =H29 -> 199476.77
A30: Операции | B30: фев | C30: 2 | D30: 6998313.6 | E30: 7197932.7 | F30: =IF(C30<=fact_months,"",ROUND(D30*(1+Тренд!$B$8/100),2)) | G30: =IF(C30<=fact_months,E30,F30) -> 7197932.7 | H30: =G30-D30 -> 199619.03 | I30: =IF(D30=0,"",H30/D30) -> 0.028523876 | J30: =J29+H30 -> 399095.8
A31: Операции | B31: мар | C31: 3 | D31: 6910412.1 | E31: 7105429.2 | F31: =IF(C31<=fact_months,"",ROUND(D31*(1+Тренд!$B$8/100),2)) | G31: =IF(C31<=fact_months,E31,F31) -> 7105429.2 | H31: =G31-D31 -> 195017.06 | I31: =IF(D31=0,"",H31/D31) -> 0.028220757 | J31: =J30+H31 -> 594112.86
A32: Операции | B32: апр | C32: 4 | D32: 6795464 | E32: 6984312.2 | F32: =IF(C32<=fact_months,"",ROUND(D32*(1+Тренд!$B$8/100),2)) | G32: =IF(C32<=fact_months,E32,F32) -> 6984312.2 | H32: =G32-D32 -> 188848.18 | I32: =IF(D32=0,"",H32/D32) -> 0.027790329 | J32: =J31+H32 -> 782961.04
A33: Операции | B33: май | C33: 5 | D33: 6666992.5 | E33: 6842561.3 | F33: =IF(C33<=fact_months,"",ROUND(D33*(1+Тренд!$B$8/100),2)) | G33: =IF(C33<=fact_months,E33,F33) -> 6842561.3 | H33: =G33-D33 -> 175568.82 | I33: =IF(D33=0,"",H33/D33) -> 0.026334036 | J33: =J32+H33 -> 958529.86
A34: Операции | B34: июн | C34: 6 | D34: 6545282.7 | E34: 6714907.2 | F34: =IF(C34<=fact_months,"",ROUND(D34*(1+Тренд!$B$8/100),2)) | G34: =IF(C34<=fact_months,E34,F34) -> 6714907.2 | H34: =G34-D34 -> 169624.44 | I34: =IF(D34=0,"",H34/D34) -> 0.025915525 | J34: =J33+H34 -> 1128154.3
A35: Операции | B35: июл | C35: 7 | D35: 6504712.8 | E35: 6690280.9 | F35: =IF(C35<=fact_months,"",ROUND(D35*(1+Тренд!$B$8/100),2)) | G35: =IF(C35<=fact_months,E35,F35) -> 6690280.9 | H35: =G35-D35 -> 185568.16 | I35: =IF(D35=0,"",H35/D35) -> 0.028528263 | J35: =J34+H35 -> 1313722.5
A36: Операции | B36: авг | C36: 8 | D36: 6518236.1 | E36: 6692832 | F36: =IF(C36<=fact_months,"",ROUND(D36*(1+Тренд!$B$8/100),2)) | G36: =IF(C36<=fact_months,E36,F36) -> 6692832 | H36: =G36-D36 -> 174595.95 | I36: =IF(D36=0,"",H36/D36) -> 0.026785767 | J36: =J35+H36 -> 1488318.4
A37: Операции | B37: сен | C37: 9 | D37: 6660230.9 | F37: =IF(C37<=fact_months,"",ROUND(D37*(1+Тренд!$B$8/100),2)) -> 6841693 | G37: =IF(C37<=fact_months,E37,F37) -> 6841693 | H37: =G37-D37 -> 181462.15 | I37: =IF(D37=0,"",H37/D37) -> 0.027245625 | J37: =J36+H37 -> 1669780.6
A38: Операции | B38: окт | C38: 10 | D38: 6802225.6 | F38: =IF(C38<=fact_months,"",ROUND(D38*(1+Тренд!$B$8/100),2)) -> 6987556.5 | G38: =IF(C38<=fact_months,E38,F38) -> 6987556.5 | H38: =G38-D38 -> 185330.88 | I38: =IF(D38=0,"",H38/D38) -> 0.027245624 | J38: =J37+H38 -> 1855111.4
A39: Операции | B39: ноя | C39: 11 | D39: 6856318.9 | F39: =IF(C39<=fact_months,"",ROUND(D39*(1+Тренд!$B$8/100),2)) -> 7043123.6 | G39: =IF(C39<=fact_months,E39,F39) -> 7043123.6 | H39: =G39-D39 -> 186804.69 | I39: =IF(D39=0,"",H39/D39) -> 0.027245625 | J39: =J38+H39 -> 2041916.1
A40: Операции | B40: дек | C40: 12 | D40: 6863080.5 | F40: =IF(C40<=fact_months,"",ROUND(D40*(1+Тренд!$B$8/100),2)) -> 7050069.4 | G40: =IF(C40<=fact_months,E40,F40) -> 7050069.4 | H40: =G40-D40 -> 186988.91 | I40: =IF(D40=0,"",H40/D40) -> 0.027245624 | J40: =J39+H40 -> 2228905
A41: Производство | B41: янв | C41: 1 | D41: 6664509.2 | E41: 6853388.1 | F41: =IF(C41<=fact_months,"",ROUND(D41*(1+Тренд!$B$9/100),2)) | G41: =IF(C41<=fact_months,E41,F41) -> 6853388.1 | H41: =G41-D41 -> 188878.9 | I41: =IF(D41=0,"",H41/D41) -> 0.028341007 | J41: =H41 -> 188878.9
...

Sheet Месяцы
A1: Итог по компании за каждый месяц
A2: Две разные величины. Месячное отклонение говорит, насколько этот месяц ушёл от плана; накопительное несёт в себе все месяцы до него. Месяц может стать лучше, а накопительное — продолжать расти.
A5: Месяц | B5: № | C5: План, ₽ | D5: Ожидание, ₽ | E5: Отклонение, ₽ | F5: Отклонение, % | G5: Накопительно, ₽
A6: янв | B6: 1 | C6: =SUMIF(Данные!$C$5:$C$88,$B6,Данные!$D$5:$D$88) -> 45079427 | D6: =SUMIF(Данные!$C$5:$C$88,$B6,Данные!$G$5:$G$88) -> 46746695 | E6: =D6-C6 -> 1667268.2 | F6: =E6/C6 -> 0.036985125 | G6: =E6 -> 1667268.2
A7: фев | B7: 2 | C7: =SUMIF(Данные!$C$5:$C$88,$B7,Данные!$D$5:$D$88) -> 44949139 | D7: =SUMIF(Данные!$C$5:$C$88,$B7,Данные!$G$5:$G$88) -> 46641833 | E7: =D7-C7 -> 1692693.4 | F7: =E7/C7 -> 0.037657972 | G7: =G6+E7 -> 3359961.7
A8: мар | B8: 3 | C8: =SUMIF(Данные!$C$5:$C$88,$B8,Данные!$D$5:$D$88) -> 44384561 | D8: =SUMIF(Данные!$C$5:$C$88,$B8,Данные!$G$5:$G$88) -> 46063714 | E8: =D8-C8 -> 1679153.6 | F8: =E8/C8 -> 0.03783193 | G8: =G7+E8 -> 5039115.2
A9: апр | B9: 4 | C9: =SUMIF(Данные!$C$5:$C$88,$B9,Данные!$D$5:$D$88) -> 43646266 | D9: =SUMIF(Данные!$C$5:$C$88,$B9,Данные!$G$5:$G$88) -> 45267506 | E9: =D9-C9 -> 1621240.1 | F9: =E9/C9 -> 0.03714499 | G9: =G8+E9 -> 6660355.3
A10: май | B10: 5 | C10: =SUMIF(Данные!$C$5:$C$88,$B10,Данные!$D$5:$D$88) -> 42821112 | D10: =SUMIF(Данные!$C$5:$C$88,$B10,Данные!$G$5:$G$88) -> 44425080 | E10: =D10-C10 -> 1603967.4 | F10: =E10/C10 -> 0.037457398 | G10: =G9+E10 -> 8264322.8
A11: июн | B11: 6 | C11: =SUMIF(Данные!$C$5:$C$88,$B11,Данные!$D$5:$D$88) -> 42039388 | D11: =SUMIF(Данные!$C$5:$C$88,$B11,Данные!$G$5:$G$88) -> 43595396 | E11: =D11-C11 -> 1556007.4 | F11: =E11/C11 -> 0.037013083 | G11: =G10+E11 -> 9820330.1
A12: июл | B12: 7 | C12: =SUMIF(Данные!$C$5:$C$88,$B12,Данные!$D$5:$D$88) -> 41778814 | D12: =SUMIF(Данные!$C$5:$C$88,$B12,Данные!$G$5:$G$88) -> 43358209 | E12: =D12-C12 -> 1579395.5 | F12: =E12/C12 -> 0.037803743 | G12: =G11+E12 -> 11399726
A13: авг | B13: 8 | C13: =SUMIF(Данные!$C$5:$C$88,$B13,Данные!$D$5:$D$88) -> 41865672 | D13: =SUMIF(Данные!$C$5:$C$88,$B13,Данные!$G$5:$G$88) -> 43437526 | E13: =D13-C13 -> 1571854.4 | F13: =E13/C13 -> 0.037545185 | G13: =G12+E13 -> 12971580
A14: сен | B14: 9 | C14: =SUMIF(Данные!$C$5:$C$88,$B14,Данные!$D$5:$D$88) -> 42777683 | D14: =SUMIF(Данные!$C$5:$C$88,$B14,Данные!$G$5:$G$88) -> 44379700 | E14: =D14-C14 -> 1602017 | F14: =E14/C14 -> 0.037449831 | G14: =G13+E14 -> 14573597
A15: окт | B15: 10 | C15: =SUMIF(Данные!$C$5:$C$88,$B15,Данные!$D$5:$D$88) -> 43689695 | D15: =SUMIF(Данные!$C$5:$C$88,$B15,Данные!$G$5:$G$88) -> 45325867 | E15: =D15-C15 -> 1636171.7 | F15: =E15/C15 -> 0.037449831 | G15: =G14+E15 -> 16209769
A16: ноя | B16: 11 | C16: =SUMIF(Данные!$C$5:$C$88,$B16,Данные!$D$5:$D$88) -> 44037128 | D16: =SUMIF(Данные!$C$5:$C$88,$B16,Данные!$G$5:$G$88) -> 45686311 | E16: =D16-C16 -> 1649183 | F16: =E16/C16 -> 0.037449831 | G16: =G15+E16 -> 17858952
A17: дек | B17: 12 | C17: =SUMIF(Данные!$C$5:$C$88,$B17,Данные!$D$5:$D$88) -> 44080557 | D17: =SUMIF(Данные!$C$5:$C$88,$B17,Данные!$G$5:$G$88) -> 45731366 | E17: =D17-C17 -> 1650809.4 | F17: =E17/C17 -> 0.037449831 | G17: =G16+E17 -> 19509761
A18: ГОД | C18: =SUM(C6:C17) -> 5.2114944e+08 | D18: =SUM(D6:D17) -> 5.406592e+08 | E18: =SUM(E6:E17) -> 19509761 | F18: =E18/C18 -> 0.037436021

Sheet Подразделения
A1: По подразделениям: месяцы с фактом и год
A2: Знак отклонения внутри подразделения устойчив: оно весь год либо выше плана, либо ниже. Перерасход обычно сидит в одном месте.
A4: Подразделение | B4: План с начала года, ₽ | C4: Факт с начала года, ₽ | D4: Отклонение, ₽ | E4: Отклонение, % | F4: План на год, ₽ | G4: Ожидание на год, ₽ | H4: Отклонение за год, ₽ | I4: За год, %
A5: Разработка | B5: =SUMIF(Данные!$C$5:$C$16,"<="&fact_months,Данные!$D$5:$D$16) -> 84110959 | C5: =SUMIF(Данные!$C$5:$C$16,"<="&fact_months,Данные!$E$5:$E$16) -> 86611489 | D5: =C5-B5 -> 2500530.2 | E5: =D5/B5 -> 0.029728946 | F5: =SUM(Данные!$D$5:$D$16) -> 1.2648265e+08 | G5: =SUM(Данные!$G$5:$G$16) -> 1.3024268e+08 | H5: =G5-F5 -> 3760035 | I5: =H5/F5 -> 0.029727675
A6: Продажи | B6: =SUMIF(Данные!$C$17:$C$28,"<="&fact_months,Данные!$D$17:$D$28) -> 61124648 | C6: =SUMIF(Данные!$C$17:$C$28,"<="&fact_months,Данные!$E$17:$E$28) -> 66954737 | D6: =C6-B6 -> 5830089.2 | E6: =D6/B6 -> 0.095380333 | F6: =SUM(Данные!$D$17:$D$28) -> 91916763 | G6: =SUM(Данные!$G$17:$G$28) -> 1.0069011e+08 | H6: =G6-F6 -> 8773347.8 | I6: =H6/F6 -> 0.095448833
A7: Операции | B7: =SUMIF(Данные!$C$29:$C$40,"<="&fact_months,Данные!$D$29:$D$40) -> 53958012 | C7: =SUMIF(Данные!$C$29:$C$40,"<="&fact_months,Данные!$E$29:$E$40) -> 55446331 | D7: =C7-B7 -> 1488318.4 | E7: =D7/B7 -> 0.027582899 | F7: =SUM(Данные!$D$29:$D$40) -> 81139868 | G7: =SUM(Данные!$G$29:$G$40) -> 83368773 | H7: =G7-F7 -> 2228905 | I7: =H7/F7 -> 0.027469912
A8: Производство | B8: =SUMIF(Данные!$C$41:$C$52,"<="&fact_months,Данные!$D$41:$D$52) -> 51235822 | C8: =SUMIF(Данные!$C$41:$C$52,"<="&fact_months,Данные!$E$41:$E$52) -> 52734274 | D8: =C8-B8 -> 1498452.1 | E8: =D8/B8 -> 0.029246181 | F8: =SUM(Данные!$D$41:$D$52) -> 77046349 | G8: =SUM(Данные!$G$41:$G$52) -> 79302959 | H8: =G8-F8 -> 2256609.6 | I8: =H8/F8 -> 0.029288987
A9: Маркетинг | B9: =SUMIF(Данные!$C$53:$C$64,"<="&fact_months,Данные!$D$53:$D$64) -> 48944286 | C9: =SUMIF(Данные!$C$53:$C$64,"<="&fact_months,Данные!$E$53:$E$64) -> 50192940 | D9: =C9-B9 -> 1248654 | E9: =D9/B9 -> 0.025511741 | F9: =SUM(Данные!$D$53:$D$64) -> 73600430 | G9: =SUM(Данные!$G$53:$G$64) -> 75484780 | H9: =G9-F9 -> 1884350.1 | I9: =H9/F9 -> 0.025602434
A10: Поддержка клиентов | B10: =SUMIF(Данные!$C$65:$C$76,"<="&fact_months,Данные!$D$65:$D$76) -> 28559494 | C10: =SUMIF(Данные!$C$65:$C$76,"<="&fact_months,Данные!$E$65:$E$76) -> 29200616 | D10: =C10-B10 -> 641121.94 | E10: =D10/B10 -> 0.022448645 | F10: =SUM(Данные!$D$65:$D$76) -> 42946608 | G10: =SUM(Данные!$G$65:$G$76) -> 43905993 | H10: =G10-F10 -> 959384.63 | I10: =H10/F10 -> 0.022339008
A11: Юристы | B11: =SUMIF(Данные!$C$77:$C$88,"<="&fact_months,Данные!$D$77:$D$88) -> 18631157 | C11: =SUMIF(Данные!$C$77:$C$88,"<="&fact_months,Данные!$E$77:$E$88) -> 18395571 | D11: =C11-B11 -> -235585.78 | E11: =D11/B11 -> -0.012644721 | F11: =SUM(Данные!$D$77:$D$88) -> 28016778 | G11: =SUM(Данные!$G$77:$G$88) -> 27663907 | H11: =G11-F11 -> -352870.92 | I11: =H11/F11 -> -0.012594986
A12: ИТОГО | B12: =SUM(B5:B11) -> 3.4656438e+08 | C12: =SUM(C5:C11) -> 3.5953596e+08 | D12: =SUM(D5:D11) -> 12971580 | E12: =D12/B12 -> 0.037429063 | F12: =SUM(F5:F11) -> 5.2114944e+08 | G12: =SUM(G5:G11) -> 5.406592e+08 | H12: =SUM(H5:H11) -> 19509761 | I12: =H12/F12 -> 0.037436021

Sheet Итоги
A1: Итоги | D1: cells_for_check
A2: Каждая цифра здесь — формула. Поменяйте факт на листе «Данные» и посмотрите, как всё пересчитается. | D2: plan8 | E2: B5
D3: fact8 | E3: B6
A4: Месяцы с фактом | D4: fc4 | E4: B12
A5: План с начала года | B5: =SUMIF(Месяцы!$B$6:$B$17,"<="&fact_months,Месяцы!$C$6:$C$17) -> 3.4656438e+08 | D5: yplan | E5: B17
A6: Факт с начала года | B6: =SUMIF(Месяцы!$B$6:$B$17,"<="&fact_months,Месяцы!$D$6:$D$17) -> 3.5953596e+08 | D6: yexp | E6: B18
A7: Отклонение | B7: =B6-B5 -> 12971580 | D7: ydelta | E7: B19
A8: В % к плану | B8: =B7/B5 -> 0.037429063 | D8: cross | E8: B23
D9: signal | E9: B21
A10: Оставшиеся месяцы
A11: План | B11: =B17-B5 -> 1.7458506e+08
A12: Прогноз | B12: =B18-B6 -> 1.8112324e+08
A13: Отклонение | B13: =B12-B11 -> 6538181.1
A14: В % к плану | B14: =B13/B11 -> 0.037449831
A16: Год целиком
A17: План | B17: =Месяцы!$C$18 -> 5.2114944e+08
A18: Ожидание (факт + прогноз) | B18: =Месяцы!$D$18 -> 5.406592e+08
A19: Отклонение | B19: =B18-B17 -> 19509761
A20: В % к плану | B20: =B19/B17 -> 0.037436021
A21: Сигнал | B21: =IF(B20>=alert_threshold,"проблема","в пределах порога") -> проблема
A23: Первый месяц, когда накопительно выше плана | B23: =IFERROR(INDEX(Месяцы!$A$6:$A$17,MATCH(TRUE,INDEX(Месяцы!$G$6:$G$17>0,0),0)),"нет") -> янв
A25: Отклонение везде — ожидание минус план. Плюс значит, что компания потратила больше плана, минус — меньше. Столбцы D и E — служебные: по ним проверочный скрипт находит итоговые ячейки.

Sheet Пояснения
A1: Пояснения и метод
A3: Цвета
A4: Жёлтый | B4: Исходные данные. Берутся из CSV, не считаются.
A5: Голубой | B5: Считается формулой. Эти ячейки пересчитываются сами.
A6: Зелёный | B6: Настройка на листе «Настройки». Их можно менять.
A8: Порядок расчёта
A9: 1. План | B9: ФОТ подразделения на год — оклады и переменная часть, без страховых взносов работодателя. Разложен на двенадцать месяцев с учётом сезонности отпусков: выше в начале и конце года, ниже летом. Коэффициенты сезонности в сумме дают двенадцать, поэтому сезонность двигает деньги внутри года, не меняя годовую сумму.
A10: 2. Факт | B10: Месяцы 1..fact_months. Знак отклонения в подразделении устойчив: оно весь год либо выше плана, либо ниже. Одно подразделение заметно выбивается из ряда: бюджет редко расходится ровно, он расходится в одном месте.
A11: 3. Прогноз | B11: На оставшиеся месяцы — план, умноженный на (1 + тренд подразделения). Тренд — отклонение подразделения от плана в месяцы с фактом, лист «Тренд». Прогноз «ровно по плану» молча предполагал бы, что перерасход с сентября исчезнет.
A12: 4. Отклонение | B12: Ожидание минус план. Плюс — перерасход. Показано и по месяцам, и нарастающим итогом с января.
A13: 5. Год и сигнал | B13: План против факта и прогноза. Если ожидание на год выше плана на порог или больше (настройка alert_threshold, по умолчанию 3%), сигнал — «проблема».
A15: Две величины, которые не надо путать
A16: Месячное отклонение | B16: Насколько один месяц ушёл от плана. Отвечает на вопрос: этот месяц хуже прошлого?
A17: Накопительное отклонение | B17: То же самое, сложенное с января. Отвечает на другой вопрос: какая часть годового бюджета уже ушла сверх плана. Месяц может улучшиться, а накопительное — расти. Обе цифры верны; одну нельзя читать вместо другой.
A19: Чего эта модель не делает
A20: Не объясняет отклонения | B20: Показывает, где и сколько, но не почему. Причины выясняются в разговоре с руководителем подразделения, а не на экране.
A21: Страховые взносы | B21: В план и факт не входят: ФОТ здесь — оклады и переменная часть. Если ваш бюджет ведётся вместе со взносами, загрузите суммы со взносами — модель считает отклонения от того, что в файле.
A22: Данные смоделированы | B22: Получены генератором со сидом, а не из реальной компании. Модель показывает подход к контролю бюджета и не является юридической или бухгалтерской консультацией.
