Workbook
Name ceiling: Настройки!$B$11
Name implementation_month: Настройки!$B$8
Name rate_above: Настройки!$B$10
Name rate_below: Настройки!$B$9
Name threshold_pct: Настройки!$B$7

Sheet Настройки
A1: Настройки модели
A2: Демо-данные, 212 сотрудников (смоделированы)
A4: Менять можно только зелёные ячейки. Всё остальное пересчитывается само.
A6: Имя | B6: Значение | C6: Что это | D6: Пояснение
A7: threshold_pct | B7: 5 | C7: Допустимый остаток, % | D7: Целевой необъяснённый разрыв для минимального сценария. Внутренний ориентир компании: закон РФ такого порога не задаёт (ст. 22 ТК РФ требует равной оплаты за труд равной ценности, ст. 132 запрещает дискриминацию в оплате).
A8: implementation_month | B8: 7 | C8: Месяц выравнивания | D8: 1 = январь. Определяет затраты в текущем году: (13 - m) / 12.
A9: rate_below | B9: 30 | C9: Тариф взносов до предельной базы, % | D9: РФ, п. 3 ст. 425 НК РФ: единый тариф страховых взносов 30%. Применяется к части прибавки, которая укладывается в предельную базу. Взносы на травматизм (0,2–8,5%) не включены — добавьте свой тариф к обеим ставкам. У МСП с правом на льготу и IT-компаний тарифы ниже.
A10: rate_above | B10: 15.1 | C10: Тариф взносов сверх предельной базы, % | D10: РФ, п. 3 ст. 425 НК РФ: 15,1%. Применяется к части прибавки, которая выводит оклад за предельную базу.
A11: ceiling | B11: 2979000 | C11: Единая предельная база, ₽ | D11: РФ 2026: 2 979 000 ₽ в год (Постановление Правительства РФ от 31.10.2025 № 1705). Сравнивается с фактическим окладом сотрудника.
A14: Исходные данные
A15: На листе «Данные» — зафиксированная выгрузка. Генератор демо-данных использует генератор псевдослучайных чисел (mulberry32 + Box-Muller), который нельзя побайтно повторить формулами Excel, поэтому массив выгружен числами. Всё, что посчитано поверх него, — живые формулы.

Sheet Данные
A1: Данные и расчёт по сотрудникам
A2: Жёлтое — исходные данные из CSV. Голубое — считается формулой. Формулы ссылаются на лист «Категории», где считаются разрывы по категориям.
A4: id | B4: category | C4: gender | D4: base_salary | E4: variable_pay | F4: tenure_years | G4: grade | H4: fte | I4: months_worked | J4: factor | K4: n_base | L4: n_var | M4: n_total | N4: actual_total | O4: median_cat | P4: recip_min | Q4: deficit_min | R4: share_min | S4: uplift_norm_min | T4: uplift_act_min | U4: contrib_min | V4: cost_min | W4: recip_full | X4: deficit_full | Y4: share_full | Z4: uplift_norm_full | AA4: uplift_act_full | AB4: contrib_full | AC4: cost_full | AD4: _rank_cat | AE4: _n_cat | AF4: _rank_sex | AG4: _n_sex
A5: E001 | B5: Разработка | C5: M | D5: 2279487.1 | E5: 326755.69 | F5: 5.6 | G5: 8 | H5: 1 | I5: 12 | J5: =H5*(I5/12) -> 1 | K5: =D5/J5 -> 2279487.1 | L5: =E5/J5 -> 326755.69 | M5: =K5+L5 -> 2606242.8 | N5: =D5+E5 -> 2606242.8 | O5: =(SUMIFS($M$5:$M$216,$B$5:$B$216,B5,$AD$5:$AD$216,INT((AE5+1)/2))+SUMIFS($M$5:$M$216,$B$5:$B$216,B5,$AD$5:$AD$216,INT(AE5/2)+1))/2 -> 2878288.9 | P5: =IF(AND(C5="F",M5<O5,SUMIFS(Категории!$Z$5:$Z$11,Категории!$A$5:$A$11,B5)=1),1,0) -> 0 | Q5: =IF(P5=1,O5-M5,0) -> 0 | R5: =IF(AND(P5=1,SUMIFS(Категории!$AA$5:$AA$11,Категории!$A$5:$A$11,B5)>0),Q5/SUMIFS(Категории!$AA$5:$AA$11,Категории!$A$5:$A$11,B5),0) -> 0 | S5: =R5*SUMIFS(Категории!$AB$5:$AB$11,Категории!$A$5:$A$11,B5) -> 0 | T5: =S5*J5 -> 0 | U5: =IF(T5<=0,0,(rate_below/100)*MIN(T5,MAX(0,ceiling-D5))+(rate_above/100)*(T5-MIN(T5,MAX(0,ceiling-D5)))) -> 0 | V5: =T5+U5 -> 0 | W5: =IF(AND(C5="F",M5<O5,SUMIFS(Категории!$AH$5:$AH$11,Категории!$A$5:$A$11,B5)=1),1,0) -> 0 | X5: =IF(W5=1,O5-M5,0) -> 0 | Y5: =IF(AND(W5=1,SUMIFS(Категории!$AI$5:$AI$11,Категории!$A$5:$A$11,B5)>0),X5/SUMIFS(Категории!$AI$5:$AI$11,Категории!$A$5:$A$11,B5),0) -> 0 | Z5: =Y5*SUMIFS(Категории!$AJ$5:$AJ$11,Категории!$A$5:$A$11,B5) -> 0 | AA5: =Z5*J5 -> 0 | AB5: =IF(AA5<=0,0,(rate_below/100)*MIN(AA5,MAX(0,ceiling-D5))+(rate_above/100)*(AA5-MIN(AA5,MAX(0,ceiling-D5)))) -> 0 | AC5: =AA5+AB5 -> 0 | AD5: =SUMPRODUCT(($B$5:$B$216=B5)*($M$5:$M$216<M5))+SUMPRODUCT(($B$5:$B$216=B5)*($M$5:$M$216=M5)*(ROW($M$5:$M$216)<ROW(M5)))+1 -> 17 | AE5: =COUNTIF($B$5:$B$216,B5) -> 44 | AF5: =SUMPRODUCT(($B$5:$B$216=B5)*($C$5:$C$216=C5)*($M$5:$M$216<M5))+SUMPRODUCT(($B$5:$B$216=B5)*($C$5:$C$216=C5)*($M$5:$M$216=M5)*(ROW($M$5:$M$216)<ROW(M5)))+1 -> 11 | AG5: =COUNTIFS($B$5:$B$216,B5,$C$5:$C$216,C5) -> 32
A6: E002 | B6: Разработка | C6: M | D6: 2639865.7 | E6: 353090.63 | F6: 8.9 | G6: 9 | H6: 1 | I6: 12 | J6: =H6*(I6/12) -> 1 | K6: =D6/J6 -> 2639865.7 | L6: =E6/J6 -> 353090.63 | M6: =K6+L6 -> 2992956.4 | N6: =D6+E6 -> 2992956.4 | O6: =(SUMIFS($M$5:$M$216,$B$5:$B$216,B6,$AD$5:$AD$216,INT((AE6+1)/2))+SUMIFS($M$5:$M$216,$B$5:$B$216,B6,$AD$5:$AD$216,INT(AE6/2)+1))/2 -> 2878288.9 | P6: =IF(AND(C6="F",M6<O6,SUMIFS(Категории!$Z$5:$Z$11,Категории!$A$5:$A$11,B6)=1),1,0) -> 0 | Q6: =IF(P6=1,O6-M6,0) -> 0 | R6: =IF(AND(P6=1,SUMIFS(Категории!$AA$5:$AA$11,Категории!$A$5:$A$11,B6)>0),Q6/SUMIFS(Категории!$AA$5:$AA$11,Категории!$A$5:$A$11,B6),0) -> 0 | S6: =R6*SUMIFS(Категории!$AB$5:$AB$11,Категории!$A$5:$A$11,B6) -> 0 | T6: =S6*J6 -> 0 | U6: =IF(T6<=0,0,(rate_below/100)*MIN(T6,MAX(0,ceiling-D6))+(rate_above/100)*(T6-MIN(T6,MAX(0,ceiling-D6)))) -> 0 | V6: =T6+U6 -> 0 | W6: =IF(AND(C6="F",M6<O6,SUMIFS(Категории!$AH$5:$AH$11,Категории!$A$5:$A$11,B6)=1),1,0) -> 0 | X6: =IF(W6=1,O6-M6,0) -> 0 | Y6: =IF(AND(W6=1,SUMIFS(Категории!$AI$5:$AI$11,Категории!$A$5:$A$11,B6)>0),X6/SUMIFS(Категории!$AI$5:$AI$11,Категории!$A$5:$A$11,B6),0) -> 0 | Z6: =Y6*SUMIFS(Категории!$AJ$5:$AJ$11,Категории!$A$5:$A$11,B6) -> 0 | AA6: =Z6*J6 -> 0 | AB6: =IF(AA6<=0,0,(rate_below/100)*MIN(AA6,MAX(0,ceiling-D6))+(rate_above/100)*(AA6-MIN(AA6,MAX(0,ceiling-D6)))) -> 0 | AC6: =AA6+AB6 -> 0 | AD6: =SUMPRODUCT(($B$5:$B$216=B6)*($M$5:$M$216<M6))+SUMPRODUCT(($B$5:$B$216=B6)*($M$5:$M$216=M6)*(ROW($M$5:$M$216)<ROW(M6)))+1 -> 25 | AE6: =COUNTIF($B$5:$B$216,B6) -> 44 | AF6: =SUMPRODUCT(($B$5:$B$216=B6)*($C$5:$C$216=C6)*($M$5:$M$216<M6))+SUMPRODUCT(($B$5:$B$216=B6)*($C$5:$C$216=C6)*($M$5:$M$216=M6)*(ROW($M$5:$M$216)<ROW(M6)))+1 -> 17 | AG6: =COUNTIFS($B$5:$B$216,B6,$C$5:$C$216,C6) -> 32
A7: E003 | B7: Разработка | C7: M | D7: 3189911.3 | E7: 450501.95 | F7: 11.8 | G7: 11 | H7: 1 | I7: 12 | J7: =H7*(I7/12) -> 1 | K7: =D7/J7 -> 3189911.3 | L7: =E7/J7 -> 450501.95 | M7: =K7+L7 -> 3640413.3 | N7: =D7+E7 -> 3640413.3 | O7: =(SUMIFS($M$5:$M$216,$B$5:$B$216,B7,$AD$5:$AD$216,INT((AE7+1)/2))+SUMIFS($M$5:$M$216,$B$5:$B$216,B7,$AD$5:$AD$216,INT(AE7/2)+1))/2 -> 2878288.9 | P7: =IF(AND(C7="F",M7<O7,SUMIFS(Категории!$Z$5:$Z$11,Категории!$A$5:$A$11,B7)=1),1,0) -> 0 | Q7: =IF(P7=1,O7-M7,0) -> 0 | R7: =IF(AND(P7=1,SUMIFS(Категории!$AA$5:$AA$11,Категории!$A$5:$A$11,B7)>0),Q7/SUMIFS(Категории!$AA$5:$AA$11,Категории!$A$5:$A$11,B7),0) -> 0 | S7: =R7*SUMIFS(Категории!$AB$5:$AB$11,Категории!$A$5:$A$11,B7) -> 0 | T7: =S7*J7 -> 0 | U7: =IF(T7<=0,0,(rate_below/100)*MIN(T7,MAX(0,ceiling-D7))+(rate_above/100)*(T7-MIN(T7,MAX(0,ceiling-D7)))) -> 0 | V7: =T7+U7 -> 0 | W7: =IF(AND(C7="F",M7<O7,SUMIFS(Категории!$AH$5:$AH$11,Категории!$A$5:$A$11,B7)=1),1,0) -> 0 | X7: =IF(W7=1,O7-M7,0) -> 0 | Y7: =IF(AND(W7=1,SUMIFS(Категории!$AI$5:$AI$11,Категории!$A$5:$A$11,B7)>0),X7/SUMIFS(Категории!$AI$5:$AI$11,Категории!$A$5:$A$11,B7),0) -> 0 | Z7: =Y7*SUMIFS(Категории!$AJ$5:$AJ$11,Категории!$A$5:$A$11,B7) -> 0 | AA7: =Z7*J7 -> 0 | AB7: =IF(AA7<=0,0,(rate_below/100)*MIN(AA7,MAX(0,ceiling-D7))+(rate_above/100)*(AA7-MIN(AA7,MAX(0,ceiling-D7)))) -> 0 | AC7: =AA7+AB7 -> 0 | AD7: =SUMPRODUCT(($B$5:$B$216=B7)*($M$5:$M$216<M7))+SUMPRODUCT(($B$5:$B$216=B7)*($M$5:$M$216=M7)*(ROW($M$5:$M$216)<ROW(M7)))+1 -> 40 | AE7: =COUNTIF($B$5:$B$216,B7) -> 44 | AF7: =SUMPRODUCT(($B$5:$B$216=B7)*($C$5:$C$216=C7)*($M$5:$M$216<M7))+SUMPRODUCT(($B$5:$B$216=B7)*($C$5:$C$216=C7)*($M$5:$M$216=M7)*(ROW($M$5:$M$216)<ROW(M7)))+1 -> 28 | AG7: =COUNTIFS($B$5:$B$216,B7,$C$5:$C$216,C7) -> 32
A8: E004 | B8: Разработка | C8: M | D8: 2931387.5 | E8: 351548.24 | F8: 7.4 | G8: 10 | H8: 1 | I8: 12 | J8: =H8*(I8/12) -> 1 | K8: =D8/J8 -> 2931387.5 | L8: =E8/J8 -> 351548.24 | M8: =K8+L8 -> 3282935.7 | N8: =D8+E8 -> 3282935.7 | O8: =(SUMIFS($M$5:$M$216,$B$5:$B$216,B8,$AD$5:$AD$216,INT((AE8+1)/2))+SUMIFS($M$5:$M$216,$B$5:$B$216,B8,$AD$5:$AD$216,INT(AE8/2)+1))/2 -> 2878288.9 | P8: =IF(AND(C8="F",M8<O8,SUMIFS(Категории!$Z$5:$Z$11,Категории!$A$5:$A$11,B8)=1),1,0) -> 0 | Q8: =IF(P8=1,O8-M8,0) -> 0 | R8: =IF(AND(P8=1,SUMIFS(Категории!$AA$5:$AA$11,Категории!$A$5:$A$11,B8)>0),Q8/SUMIFS(Категории!$AA$5:$AA$11,Категории!$A$5:$A$11,B8),0) -> 0 | S8: =R8*SUMIFS(Категории!$AB$5:$AB$11,Категории!$A$5:$A$11,B8) -> 0 | T8: =S8*J8 -> 0 | U8: =IF(T8<=0,0,(rate_below/100)*MIN(T8,MAX(0,ceiling-D8))+(rate_above/100)*(T8-MIN(T8,MAX(0,ceiling-D8)))) -> 0 | V8: =T8+U8 -> 0 | W8: =IF(AND(C8="F",M8<O8,SUMIFS(Категории!$AH$5:$AH$11,Категории!$A$5:$A$11,B8)=1),1,0) -> 0 | X8: =IF(W8=1,O8-M8,0) -> 0 | Y8: =IF(AND(W8=1,SUMIFS(Категории!$AI$5:$AI$11,Категории!$A$5:$A$11,B8)>0),X8/SUMIFS(Категории!$AI$5:$AI$11,Категории!$A$5:$A$11,B8),0) -> 0 | Z8: =Y8*SUMIFS(Категории!$AJ$5:$AJ$11,Категории!$A$5:$A$11,B8) -> 0 | AA8: =Z8*J8 -> 0 | AB8: =IF(AA8<=0,0,(rate_below/100)*MIN(AA8,MAX(0,ceiling-D8))+(rate_above/100)*(AA8-MIN(AA8,MAX(0,ceiling-D8)))) -> 0 | AC8: =AA8+AB8 -> 0 | AD8: =SUMPRODUCT(($B$5:$B$216=B8)*($M$5:$M$216<M8))+SUMPRODUCT(($B$5:$B$216=B8)*($M$5:$M$216=M8)*(ROW($M$5:$M$216)<ROW(M8)))+1 -> 33 | AE8: =COUNTIF($B$5:$B$216,B8) -> 44 | AF8: =SUMPRODUCT(($B$5:$B$216=B8)*($C$5:$C$216=C8)*($M$5:$M$216<M8))+SUMPRODUCT(($B$5:$B$216=B8)*($C$5:$C$216=C8)*($M$5:$M$216=M8)*(ROW($M$5:$M$216)<ROW(M8)))+1 -> 22 | AG8: =COUNTIFS($B$5:$B$216,B8,$C$5:$C$216,C8) -> 32
A9: E005 | B9: Разработка | C9: F | D9: 2781538.5 | E9: 266166.46 | F9: 6.6 | G9: 10 | H9: 1 | I9: 12 | J9: =H9*(I9/12) -> 1 | K9: =D9/J9 -> 2781538.5 | L9: =E9/J9 -> 266166.46 | M9: =K9+L9 -> 3047704.9 | N9: =D9+E9 -> 3047704.9 | O9: =(SUMIFS($M$5:$M$216,$B$5:$B$216,B9,$AD$5:$AD$216,INT((AE9+1)/2))+SUMIFS($M$5:$M$216,$B$5:$B$216,B9,$AD$5:$AD$216,INT(AE9/2)+1))/2 -> 2878288.9 | P9: =IF(AND(C9="F",M9<O9,SUMIFS(Категории!$Z$5:$Z$11,Категории!$A$5:$A$11,B9)=1),1,0) -> 0 | Q9: =IF(P9=1,O9-M9,0) -> 0 | R9: =IF(AND(P9=1,SUMIFS(Категории!$AA$5:$AA$11,Категории!$A$5:$A$11,B9)>0),Q9/SUMIFS(Категории!$AA$5:$AA$11,Категории!$A$5:$A$11,B9),0) -> 0 | S9: =R9*SUMIFS(Категории!$AB$5:$AB$11,Категории!$A$5:$A$11,B9) -> 0 | T9: =S9*J9 -> 0 | U9: =IF(T9<=0,0,(rate_below/100)*MIN(T9,MAX(0,ceiling-D9))+(rate_above/100)*(T9-MIN(T9,MAX(0,ceiling-D9)))) -> 0 | V9: =T9+U9 -> 0 | W9: =IF(AND(C9="F",M9<O9,SUMIFS(Категории!$AH$5:$AH$11,Категории!$A$5:$A$11,B9)=1),1,0) -> 0 | X9: =IF(W9=1,O9-M9,0) -> 0 | Y9: =IF(AND(W9=1,SUMIFS(Категории!$AI$5:$AI$11,Категории!$A$5:$A$11,B9)>0),X9/SUMIFS(Категории!$AI$5:$AI$11,Категории!$A$5:$A$11,B9),0) -> 0 | Z9: =Y9*SUMIFS(Категории!$AJ$5:$AJ$11,Категории!$A$5:$A$11,B9) -> 0 | AA9: =Z9*J9 -> 0 | AB9: =IF(AA9<=0,0,(rate_below/100)*MIN(AA9,MAX(0,ceiling-D9))+(rate_above/100)*(AA9-MIN(AA9,MAX(0,ceiling-D9)))) -> 0 | AC9: =AA9+AB9 -> 0 | AD9: =SUMPRODUCT(($B$5:$B$216=B9)*($M$5:$M$216<M9))+SUMPRODUCT(($B$5:$B$216=B9)*($M$5:$M$216=M9)*(ROW($M$5:$M$216)<ROW(M9)))+1 -> 26 | AE9: =COUNTIF($B$5:$B$216,B9) -> 44 | AF9: =SUMPRODUCT(($B$5:$B$216=B9)*($C$5:$C$216=C9)*($M$5:$M$216<M9))+SUMPRODUCT(($B$5:$B$216=B9)*($C$5:$C$216=C9)*($M$5:$M$216=M9)*(ROW($M$5:$M$216)<ROW(M9)))+1 -> 9 | AG9: =COUNTIFS($B$5:$B$216,B9,$C$5:$C$216,C9) -> 12
A10: E006 | B10: Разработка | C10: M | D10: 2409927.6 | E10: 250698.94 | F10: 5.5 | G10: 9 | H10: 1 | I10: 12 | J10: =H10*(I10/12) -> 1 | K10: =D10/J10 -> 2409927.6 | L10: =E10/J10 -> 250698.94 | M10: =K10+L10 -> 2660626.5 | N10: =D10+E10 -> 2660626.5 | O10: =(SUMIFS($M$5:$M$216,$B$5:$B$216,B10,$AD$5:$AD$216,INT((AE10+1)/2))+SUMIFS($M$5:$M$216,$B$5:$B$216,B10,$AD$5:$AD$216,INT(AE10/2)+1))/2 -> 2878288.9 | P10: =IF(AND(C10="F",M10<O10,SUMIFS(Категории!$Z$5:$Z$11,Категории!$A$5:$A$11,B10)=1),1,0) -> 0 | Q10: =IF(P10=1,O10-M10,0) -> 0 | R10: =IF(AND(P10=1,SUMIFS(Категории!$AA$5:$AA$11,Категории!$A$5:$A$11,B10)>0),Q10/SUMIFS(Категории!$AA$5:$AA$11,Категории!$A$5:$A$11,B10),0) -> 0 | S10: =R10*SUMIFS(Категории!$AB$5:$AB$11,Категории!$A$5:$A$11,B10) -> 0 | T10: =S10*J10 -> 0 | U10: =IF(T10<=0,0,(rate_below/100)*MIN(T10,MAX(0,ceiling-D10))+(rate_above/100)*(T10-MIN(T10,MAX(0,ceiling-D10)))) -> 0 | V10: =T10+U10 -> 0 | W10: =IF(AND(C10="F",M10<O10,SUMIFS(Категории!$AH$5:$AH$11,Категории!$A$5:$A$11,B10)=1),1,0) -> 0 | X10: =IF(W10=1,O10-M10,0) -> 0 | Y10: =IF(AND(W10=1,SUMIFS(Категории!$AI$5:$AI$11,Категории!$A$5:$A$11,B10)>0),X10/SUMIFS(Категории!$AI$5:$AI$11,Категории!$A$5:$A$11,B10),0) -> 0 | Z10: =Y10*SUMIFS(Категории!$AJ$5:$AJ$11,Категории!$A$5:$A$11,B10) -> 0 | AA10: =Z10*J10 -> 0 | AB10: =IF(AA10<=0,0,(rate_below/100)*MIN(AA10,MAX(0,ceiling-D10))+(rate_above/100)*(AA10-MIN(AA10,MAX(0,ceiling-D10)))) -> 0 | AC10: =AA10+AB10 -> 0 | AD10: =SUMPRODUCT(($B$5:$B$216=B10)*($M$5:$M$216<M10))+SUMPRODUCT(($B$5:$B$216=B10)*($M$5:$M$216=M10)*(ROW($M$5:$M$216)<ROW(M10)))+1 -> 18 | AE10: =COUNTIF($B$5:$B$216,B10) -> 44 | AF10: =SUMPRODUCT(($B$5:$B$216=B10)*($C$5:$C$216=C10)*($M$5:$M$216<M10))+SUMPRODUCT(($B$5:$B$216=B10)*($C$5:$C$216=C10)*($M$5:$M$216=M10)*(ROW($M$5:$M$216)<ROW(M10)))+1 -> 12 | AG10: =COUNTIFS($B$5:$B$216,B10,$C$5:$C$216,C10) -> 32
A11: E007 | B11: Разработка | C11: M | D11: 1919325.4 | E11: 226608.03 | F11: 4.8 | G11: 7 | H11: 1 | I11: 12 | J11: =H11*(I11/12) -> 1 | K11: =D11/J11 -> 1919325.4 | L11: =E11/J11 -> 226608.03 | M11: =K11+L11 -> 2145933.5 | N11: =D11+E11 -> 2145933.5 | O11: =(SUMIFS($M$5:$M$216,$B$5:$B$216,B11,$AD$5:$AD$216,INT((AE11+1)/2))+SUMIFS($M$5:$M$216,$B$5:$B$216,B11,$AD$5:$AD$216,INT(AE11/2)+1))/2 -> 2878288.9 | P11: =IF(AND(C11="F",M11<O11,SUMIFS(Категории!$Z$5:$Z$11,Категории!$A$5:$A$11,B11)=1),1,0) -> 0 | Q11: =IF(P11=1,O11-M11,0) -> 0 | R11: =IF(AND(P11=1,SUMIFS(Категории!$AA$5:$AA$11,Категории!$A$5:$A$11,B11)>0),Q11/SUMIFS(Категории!$AA$5:$AA$11,Категории!$A$5:$A$11,B11),0) -> 0 | S11: =R11*SUMIFS(Категории!$AB$5:$AB$11,Категории!$A$5:$A$11,B11) -> 0 | T11: =S11*J11 -> 0 | U11: =IF(T11<=0,0,(rate_below/100)*MIN(T11,MAX(0,ceiling-D11))+(rate_above/100)*(T11-MIN(T11,MAX(0,ceiling-D11)))) -> 0 | V11: =T11+U11 -> 0 | W11: =IF(AND(C11="F",M11<O11,SUMIFS(Категории!$AH$5:$AH$11,Категории!$A$5:$A$11,B11)=1),1,0) -> 0 | X11: =IF(W11=1,O11-M11,0) -> 0 | Y11: =IF(AND(W11=1,SUMIFS(Категории!$AI$5:$AI$11,Категории!$A$5:$A$11,B11)>0),X11/SUMIFS(Категории!$AI$5:$AI$11,Категории!$A$5:$A$11,B11),0) -> 0 | Z11: =Y11*SUMIFS(Категории!$AJ$5:$AJ$11,Категории!$A$5:$A$11,B11) -> 0 | AA11: =Z11*J11 -> 0 | AB11: =IF(AA11<=0,0,(rate_below/100)*MIN(AA11,MAX(0,ceiling-D11))+(rate_above/100)*(AA11-MIN(AA11,MAX(0,ceiling-D11)))) -> 0 | AC11: =AA11+AB11 -> 0 | AD11: =SUMPRODUCT(($B$5:$B$216=B11)*($M$5:$M$216<M11))+SUMPRODUCT(($B$5:$B$216=B11)*($M$5:$M$216=M11)*(ROW($M$5:$M$216)<ROW(M11)))+1 -> 5 | AE11: =COUNTIF($B$5:$B$216,B11) -> 44 | AF11: =SUMPRODUCT(($B$5:$B$216=B11)*($C$5:$C$216=C11)*($M$5:$M$216<M11))+SUMPRODUCT(($B$5:$B$216=B11)*($C$5:$C$216=C11)*($M$5:$M$216=M11)*(ROW($M$5:$M$216)<ROW(M11)))+1 -> 3 | AG11: =COUNTIFS($B$5:$B$216,B11,$C$5:$C$216,C11) -> 32
A12: E008 | B12: Разработка | C12: M | D12: 3170943.5 | E12: 292929.59 | F12: 6.6 | G12: 11 | H12: 1 | I12: 12 | J12: =H12*(I12/12) -> 1 | K12: =D12/J12 -> 3170943.5 | L12: =E12/J12 -> 292929.59 | M12: =K12+L12 -> 3463873.1 | N12: =D12+E12 -> 3463873.1 | O12: =(SUMIFS($M$5:$M$216,$B$5:$B$216,B12,$AD$5:$AD$216,INT((AE12+1)/2))+SUMIFS($M$5:$M$216,$B$5:$B$216,B12,$AD$5:$AD$216,INT(AE12/2)+1))/2 -> 2878288.9 | P12: =IF(AND(C12="F",M12<O12,SUMIFS(Категории!$Z$5:$Z$11,Категории!$A$5:$A$11,B12)=1),1,0) -> 0 | Q12: =IF(P12=1,O12-M12,0) -> 0 | R12: =IF(AND(P12=1,SUMIFS(Категории!$AA$5:$AA$11,Категории!$A$5:$A$11,B12)>0),Q12/SUMIFS(Категории!$AA$5:$AA$11,Категории!$A$5:$A$11,B12),0) -> 0 | S12: =R12*SUMIFS(Категории!$AB$5:$AB$11,Категории!$A$5:$A$11,B12) -> 0 | T12: =S12*J12 -> 0 | U12: =IF(T12<=0,0,(rate_below/100)*MIN(T12,MAX(0,ceiling-D12))+(rate_above/100)*(T12-MIN(T12,MAX(0,ceiling-D12)))) -> 0 | V12: =T12+U12 -> 0 | W12: =IF(AND(C12="F",M12<O12,SUMIFS(Категории!$AH$5:$AH$11,Категории!$A$5:$A$11,B12)=1),1,0) -> 0 | X12: =IF(W12=1,O12-M12,0) -> 0 | Y12: =IF(AND(W12=1,SUMIFS(Категории!$AI$5:$AI$11,Категории!$A$5:$A$11,B12)>0),X12/SUMIFS(Категории!$AI$5:$AI$11,Категории!$A$5:$A$11,B12),0) -> 0 | Z12: =Y12*SUMIFS(Категории!$AJ$5:$AJ$11,Категории!$A$5:$A$11,B12) -> 0 | AA12: =Z12*J12 -> 0 | AB12: =IF(AA12<=0,0,(rate_below/100)*MIN(AA12,MAX(0,ceiling-D12))+(rate_above/100)*(AA12-MIN(AA12,MAX(0,ceiling-D12)))) -> 0 | AC12: =AA12+AB12 -> 0 | AD12: =SUMPRODUCT(($B$5:$B$216=B12)*($M$5:$M$216<M12))+SUMPRODUCT(($B$5:$B$216=B12)*($M$5:$M$216=M12)*(ROW($M$5:$M$216)<ROW(M12)))+1 -> 37 | AE12: =COUNTIF($B$5:$B$216,B12) -> 44 | AF12: =SUMPRODUCT(($B$5:$B$216=B12)*($C$5:$C$216=C12)*($M$5:$M$216<M12))+SUMPRODUCT(($B$5:$B$216=B12)*($C$5:$C$216=C12)*($M$5:$M$216=M12)*(ROW($M$5:$M$216)<ROW(M12)))+1 -> 25 | AG12: =COUNTIFS($B$5:$B$216,B12,$C$5:$C$216,C12) -> 32
A13: E009 | B13: Разработка | C13: M | D13: 2263916.5 | E13: 242939.31 | F13: 5.9 | G13: 8 | H13: 1 | I13: 12 | J13: =H13*(I13/12) -> 1 | K13: =D13/J13 -> 2263916.5 | L13: =E13/J13 -> 242939.31 | M13: =K13+L13 -> 2506855.8 | N13: =D13+E13 -> 2506855.8 | O13: =(SUMIFS($M$5:$M$216,$B$5:$B$216,B13,$AD$5:$AD$216,INT((AE13+1)/2))+SUMIFS($M$5:$M$216,$B$5:$B$216,B13,$AD$5:$AD$216,INT(AE13/2)+1))/2 -> 2878288.9 | P13: =IF(AND(C13="F",M13<O13,SUMIFS(Категории!$Z$5:$Z$11,Категории!$A$5:$A$11,B13)=1),1,0) -> 0 | Q13: =IF(P13=1,O13-M13,0) -> 0 | R13: =IF(AND(P13=1,SUMIFS(Категории!$AA$5:$AA$11,Категории!$A$5:$A$11,B13)>0),Q13/SUMIFS(Категории!$AA$5:$AA$11,Категории!$A$5:$A$11,B13),0) -> 0 | S13: =R13*SUMIFS(Категории!$AB$5:$AB$11,Категории!$A$5:$A$11,B13) -> 0 | T13: =S13*J13 -> 0 | U13: =IF(T13<=0,0,(rate_below/100)*MIN(T13,MAX(0,ceiling-D13))+(rate_above/100)*(T13-MIN(T13,MAX(0,ceiling-D13)))) -> 0 | V13: =T13+U13 -> 0 | W13: =IF(AND(C13="F",M13<O13,SUMIFS(Категории!$AH$5:$AH$11,Категории!$A$5:$A$11,B13)=1),1,0) -> 0 | X13: =IF(W13=1,O13-M13,0) -> 0 | Y13: =IF(AND(W13=1,SUMIFS(Категории!$AI$5:$AI$11,Категории!$A$5:$A$11,B13)>0),X13/SUMIFS(Категории!$AI$5:$AI$11,Категории!$A$5:$A$11,B13),0) -> 0 | Z13: =Y13*SUMIFS(Категории!$AJ$5:$AJ$11,Категории!$A$5:$A$11,B13) -> 0 | AA13: =Z13*J13 -> 0 | AB13: =IF(AA13<=0,0,(rate_below/100)*MIN(AA13,MAX(0,ceiling-D13))+(rate_above/100)*(AA13-MIN(AA13,MAX(0,ceiling-D13)))) -> 0 | AC13: =AA13+AB13 -> 0 | AD13: =SUMPRODUCT(($B$5:$B$216=B13)*($M$5:$M$216<M13))+SUMPRODUCT(($B$5:$B$216=B13)*($M$5:$M$216=M13)*(ROW($M$5:$M$216)<ROW(M13)))+1 -> 15 | AE13: =COUNTIF($B$5:$B$216,B13) -> 44 | AF13: =SUMPRODUCT(($B$5:$B$216=B13)*($C$5:$C$216=C13)*($M$5:$M$216<M13))+SUMPRODUCT(($B$5:$B$216=B13)*($C$5:$C$216=C13)*($M$5:$M$216=M13)*(ROW($M$5:$M$216)<ROW(M13)))+1 -> 9 | AG13: =COUNTIFS($B$5:$B$216,B13,$C$5:$C$216,C13) -> 32
A14: E010 | B14: Разработка | C14: M | D14: 3024298.1 | E14: 362676.52 | F14: 9.7 | G14: 10 | H14: 1 | I14: 12 | J14: =H14*(I14/12) -> 1 | K14: =D14/J14 -> 3024298.1 | L14: =E14/J14 -> 362676.52 | M14: =K14+L14 -> 3386974.6 | N14: =D14+E14 -> 3386974.6 | O14: =(SUMIFS($M$5:$M$216,$B$5:$B$216,B14,$AD$5:$AD$216,INT((AE14+1)/2))+SUMIFS($M$5:$M$216,$B$5:$B$216,B14,$AD$5:$AD$216,INT(AE14/2)+1))/2 -> 2878288.9 | P14: =IF(AND(C14="F",M14<O14,SUMIFS(Категории!$Z$5:$Z$11,Категории!$A$5:$A$11,B14)=1),1,0) -> 0 | Q14: =IF(P14=1,O14-M14,0) -> 0 | R14: =IF(AND(P14=1,SUMIFS(Категории!$AA$5:$AA$11,Категории!$A$5:$A$11,B14)>0),Q14/SUMIFS(Категории!$AA$5:$AA$11,Категории!$A$5:$A$11,B14),0) -> 0 | S14: =R14*SUMIFS(Категории!$AB$5:$AB$11,Категории!$A$5:$A$11,B14) -> 0 | T14: =S14*J14 -> 0 | U14: =IF(T14<=0,0,(rate_below/100)*MIN(T14,MAX(0,ceiling-D14))+(rate_above/100)*(T14-MIN(T14,MAX(0,ceiling-D14)))) -> 0 | V14: =T14+U14 -> 0 | W14: =IF(AND(C14="F",M14<O14,SUMIFS(Категории!$AH$5:$AH$11,Категории!$A$5:$A$11,B14)=1),1,0) -> 0 | X14: =IF(W14=1,O14-M14,0) -> 0 | Y14: =IF(AND(W14=1,SUMIFS(Категории!$AI$5:$AI$11,Категории!$A$5:$A$11,B14)>0),X14/SUMIFS(Категории!$AI$5:$AI$11,Категории!$A$5:$A$11,B14),0) -> 0 | Z14: =Y14*SUMIFS(Категории!$AJ$5:$AJ$11,Категории!$A$5:$A$11,B14) -> 0 | AA14: =Z14*J14 -> 0 | AB14: =IF(AA14<=0,0,(rate_below/100)*MIN(AA14,MAX(0,ceiling-D14))+(rate_above/100)*(AA14-MIN(AA14,MAX(0,ceiling-D14)))) -> 0 | AC14: =AA14+AB14 -> 0 | AD14: =SUMPRODUCT(($B$5:$B$216=B14)*($M$5:$M$216<M14))+SUMPRODUCT(($B$5:$B$216=B14)*($M$5:$M$216=M14)*(ROW($M$5:$M$216)<ROW(M14)))+1 -> 36 | AE14: =COUNTIF($B$5:$B$216,B14) -> 44 | AF14: =SUMPRODUCT(($B$5:$B$216=B14)*($C$5:$C$216=C14)*($M$5:$M$216<M14))+SUMPRODUCT(($B$5:$B$216=B14)*($C$5:$C$216=C14)*($M$5:$M$216=M14)*(ROW($M$5:$M$216)<ROW(M14)))+1 -> 24 | AG14: =COUNTIFS($B$5:$B$216,B14,$C$5:$C$216,C14) -> 32
A15: E011 | B15: Разработка | C15: M | D15: 1850156.5 | E15: 259693.49 | F15: 2.8 | G15: 7 | H15: 1 | I15: 12 | J15: =H15*(I15/12) -> 1 | K15: =D15/J15 -> 1850156.5 | L15: =E15/J15 -> 259693.49 | M15: =K15+L15 -> 2109850 | N15: =D15+E15 -> 2109850 | O15: =(SUMIFS($M$5:$M$216,$B$5:$B$216,B15,$AD$5:$AD$216,INT((AE15+1)/2))+SUMIFS($M$5:$M$216,$B$5:$B$216,B15,$AD$5:$AD$216,INT(AE15/2)+1))/2 -> 2878288.9 | P15: =IF(AND(C15="F",M15<O15,SUMIFS(Категории!$Z$5:$Z$11,Категории!$A$5:$A$11,B15)=1),1,0) -> 0 | Q15: =IF(P15=1,O15-M15,0) -> 0 | R15: =IF(AND(P15=1,SUMIFS(Категории!$AA$5:$AA$11,Категории!$A$5:$A$11,B15)>0),Q15/SUMIFS(Категории!$AA$5:$AA$11,Категории!$A$5:$A$11,B15),0) -> 0 | S15: =R15*SUMIFS(Категории!$AB$5:$AB$11,Категории!$A$5:$A$11,B15) -> 0 | T15: =S15*J15 -> 0 | U15: =IF(T15<=0,0,(rate_below/100)*MIN(T15,MAX(0,ceiling-D15))+(rate_above/100)*(T15-MIN(T15,MAX(0,ceiling-D15)))) -> 0 | V15: =T15+U15 -> 0 | W15: =IF(AND(C15="F",M15<O15,SUMIFS(Категории!$AH$5:$AH$11,Категории!$A$5:$A$11,B15)=1),1,0) -> 0 | X15: =IF(W15=1,O15-M15,0) -> 0 | Y15: =IF(AND(W15=1,SUMIFS(Категории!$AI$5:$AI$11,Категории!$A$5:$A$11,B15)>0),X15/SUMIFS(Категории!$AI$5:$AI$11,Категории!$A$5:$A$11,B15),0) -> 0 | Z15: =Y15*SUMIFS(Категории!$AJ$5:$AJ$11,Категории!$A$5:$A$11,B15) -> 0 | AA15: =Z15*J15 -> 0 | AB15: =IF(AA15<=0,0,(rate_below/100)*MIN(AA15,MAX(0,ceiling-D15))+(rate_above/100)*(AA15-MIN(AA15,MAX(0,ceiling-D15)))) -> 0 | AC15: =AA15+AB15 -> 0 | AD15: =SUMPRODUCT(($B$5:$B$216=B15)*($M$5:$M$216<M15))+SUMPRODUCT(($B$5:$B$216=B15)*($M$5:$M$216=M15)*(ROW($M$5:$M$216)<ROW(M15)))+1 -> 4 | AE15: =COUNTIF($B$5:$B$216,B15) -> 44 | AF15: =SUMPRODUCT(($B$5:$B$216=B15)*($C$5:$C$216=C15)*($M$5:$M$216<M15))+SUMPRODUCT(($B$5:$B$216=B15)*($C$5:$C$216=C15)*($M$5:$M$216=M15)*(ROW($M$5:$M$216)<ROW(M15)))+1 -> 2 | AG15: =COUNTIFS($B$5:$B$216,B15,$C$5:$C$216,C15) -> 32
A16: E012 | B16: Разработка | C16: M | D16: 2436811 | E16: 299266.98 | F16: 7.7 | G16: 9 | H16: 1 | I16: 12 | J16: =H16*(I16/12) -> 1 | K16: =D16/J16 -> 2436811 | L16: =E16/J16 -> 299266.98 | M16: =K16+L16 -> 2736078 | N16: =D16+E16 -> 2736078 | O16: =(SUMIFS($M$5:$M$216,$B$5:$B$216,B16,$AD$5:$AD$216,INT((AE16+1)/2))+SUMIFS($M$5:$M$216,$B$5:$B$216,B16,$AD$5:$AD$216,INT(AE16/2)+1))/2 -> 2878288.9 | P16: =IF(AND(C16="F",M16<O16,SUMIFS(Категории!$Z$5:$Z$11,Категории!$A$5:$A$11,B16)=1),1,0) -> 0 | Q16: =IF(P16=1,O16-M16,0) -> 0 | R16: =IF(AND(P16=1,SUMIFS(Категории!$AA$5:$AA$11,Категории!$A$5:$A$11,B16)>0),Q16/SUMIFS(Категории!$AA$5:$AA$11,Категории!$A$5:$A$11,B16),0) -> 0 | S16: =R16*SUMIFS(Категории!$AB$5:$AB$11,Категории!$A$5:$A$11,B16) -> 0 | T16: =S16*J16 -> 0 | U16: =IF(T16<=0,0,(rate_below/100)*MIN(T16,MAX(0,ceiling-D16))+(rate_above/100)*(T16-MIN(T16,MAX(0,ceiling-D16)))) -> 0 | V16: =T16+U16 -> 0 | W16: =IF(AND(C16="F",M16<O16,SUMIFS(Категории!$AH$5:$AH$11,Категории!$A$5:$A$11,B16)=1),1,0) -> 0 | X16: =IF(W16=1,O16-M16,0) -> 0 | Y16: =IF(AND(W16=1,SUMIFS(Категории!$AI$5:$AI$11,Категории!$A$5:$A$11,B16)>0),X16/SUMIFS(Категории!$AI$5:$AI$11,Категории!$A$5:$A$11,B16),0) -> 0 | Z16: =Y16*SUMIFS(Категории!$AJ$5:$AJ$11,Категории!$A$5:$A$11,B16) -> 0 | AA16: =Z16*J16 -> 0 | AB16: =IF(AA16<=0,0,(rate_below/100)*MIN(AA16,MAX(0,ceiling-D16))+(rate_above/100)*(AA16-MIN(AA16,MAX(0,ceiling-D16)))) -> 0 | AC16: =AA16+AB16 -> 0 | AD16: =SUMPRODUCT(($B$5:$B$216=B16)*($M$5:$M$216<M16))+SUMPRODUCT(($B$5:$B$216=B16)*($M$5:$M$216=M16)*(ROW($M$5:$M$216)<ROW(M16)))+1 -> 21 | AE16: =COUNTIF($B$5:$B$216,B16) -> 44 | AF16: =SUMPRODUCT(($B$5:$B$216=B16)*($C$5:$C$216=C16)*($M$5:$M$216<M16))+SUMPRODUCT(($B$5:$B$216=B16)*($C$5:$C$216=C16)*($M$5:$M$216=M16)*(ROW($M$5:$M$216)<ROW(M16)))+1 -> 14 | AG16: =COUNTIFS($B$5:$B$216,B16,$C$5:$C$216,C16) -> 32
... A216: E212 | B216: Продажи | C216: M | D216: 2600752 | E216: 676195.52 | F216: 3.7 | G216: 9 | H216: 1 | I216: 12 | J216: =H216*(I216/12) -> 1 | K216: =D216/J216 -> 2600752 | L216: =E216/J216 -> 676195.52 | M216: =K216+L216 -> 3276947.5 | N216: =D216+E216 -> 3276947.5 | O216: =(SUMIFS($M$5:$M$216,$B$5:$B$216,B216,$AD$5:$AD$216,INT((AE216+1)/2))+SUMIFS($M$5:$M$216,$B$5:$B$216,B216,$AD$5:$AD$216,INT(AE216/2)+1))/2 -> 3401436.7 | P216: =IF(AND(C216="F",M216<O216,SUMIFS(Категории!$Z$5:$Z$11,Категории!$A$5:$A$11,B216)=1),1,0) -> 0 | Q216: =IF(P216=1,O216-M216,0) -> 0 | R216: =IF(AND(P216=1,SUMIFS(Категории!$AA$5:$AA$11,Категории!$A$5:$A$11,B216)>0),Q216/SUMIFS(Категории!$AA$5:$AA$11,Категории!$A$5:$A$11,B216),0) -> 0 | S216: =R216*SUMIFS(Категории!$AB$5:$AB$11,Категории!$A$5:$A$11,B216) -> 0 | T216: =S216*J216 -> 0 | U216: =IF(T216<=0,0,(rate_below/100)*MIN(T216,MAX(0,ceiling-D216))+(rate_above/100)*(T216-MIN(T216,MAX(0,ceiling-D216)))) -> 0 | V216: =T216+U216 -> 0 | W216: =IF(AND(C216="F",M216<O216,SUMIFS(Категории!$AH$5:$AH$11,Категории!$A$5:$A$11,B216)=1),1,0) -> 0 | X216: =IF(W216=1,O216-M216,0) -> 0 | Y216: =IF(AND(W216=1,SUMIFS(Категории!$AI$5:$AI$11,Категории!$A$5:$A$11,B216)>0),X216/SUMIFS(Категории!$AI$5:$AI$11,Категории!$A$5:$A$11,B216),0) -> 0 | Z216: =Y216*SUMIFS(Категории!$AJ$5:$AJ$11,Категории!$A$5:$A$11,B216) -> 0 | AA216: =Z216*J216 -> 0 | AB216: =IF(AA216<=0,0,(rate_below/100)*MIN(AA216,MAX(0,ceiling-D216))+(rate_above/100)*(AA216-MIN(AA216,MAX(0,ceiling-D216)))) -> 0 | AC216: =AA216+AB216 -> 0 | AD216: =SUMPRODUCT(($B$5:$B$216=B216)*($M$5:$M$216<M216))+SUMPRODUCT(($B$5:$B$216=B216)*($M$5:$M$216=M216)*(ROW($M$5:$M$216)<ROW(M216)))+1 -> 11 | AE216: =COUNTIF($B$5:$B$216,B216) -> 26 | AF216: =SUMPRODUCT(($B$5:$B$216=B216)*($C$5:$C$216=C216)*($M$5:$M$216<M216))+SUMPRODUCT(($B$5:$B$216=B216)*($C$5:$C$216=C216)*($M$5:$M$216=M216)*(ROW($M$5:$M$216)<ROW(M216)))+1 -> 5 | AG216: =COUNTIFS($B$5:$B$216,B216,$C$5:$C$216,C216) -> 13

Sheet Категории
A1: Расчёт по категориям
A2: Регрессия: МНК n_total на грейд и стаж внутри каждой категории, решена через явные суммы (без ЛИНЕЙН и формул массива). Условия те же, что в калькуляторе: меньше 4 наблюдений или постоянный грейд либо стаж — регрессия не строится, весь разрыв считается необъяснённым.
A4: category | B4: headcount | C4: n_F | D4: n_M | E4: mean_M | F4: mean_F | G4: median_all | H4: raw_gap_mean_% | I4: median_M | J4: median_F | K4: raw_gap_median_% | L4: var_M | M4: var_F | N4: variable_gap_% | O4: base_M | P4: base_F | Q4: base_gap_% | R4: var_grade | S4: var_tenure | T4: reg_ok | U4: coef_grade | V4: coef_tenure | W4: r2 | X4: explained_% | Y4: unexplained_% | Z4: correct_min | AA4: totalDef_min | AB4: need_min | AC4: adjust_min | AD4: contrib_min | AE4: cost_min | AF4: recip_min | AG4: unexpl_after_min | AH4: correct_full | AI4: totalDef_full | AJ4: need_full | AK4: adjust_full | AL4: contrib_full | AM4: cost_full | AN4: recip_full | AO4: unexpl_after_full | AP4: unreliable | AQ4: reverse_gap | BA4: n | BB4: Sum_g | BC4: Sum_t | BD4: Sum_y | BE4: Sum_gg | BF4: Sum_tt | BG4: Sum_gt | BH4: Sum_gy | BI4: Sum_ty | BJ4: Sum_yy | BK4: det
A5: Разработка | B5: =COUNTIF(Данные!$B$5:$B$216,$A5) -> 44 | C5: =COUNTIFS(Данные!$B$5:$B$216,$A5,Данные!$C$5:$C$216,"F") -> 12 | D5: =COUNTIFS(Данные!$B$5:$B$216,$A5,Данные!$C$5:$C$216,"M") -> 32 | E5: =IF(D5=0,0,AVERAGEIFS(Данные!$M$5:$M$216,Данные!$B$5:$B$216,$A5,Данные!$C$5:$C$216,"M")) -> 2987527.6 | F5: =IF(C5=0,0,AVERAGEIFS(Данные!$M$5:$M$216,Данные!$B$5:$B$216,$A5,Данные!$C$5:$C$216,"F")) -> 2654879.2 | G5: =IF(B5=0,0,SUMIFS(Данные!$O$5:$O$216,Данные!$B$5:$B$216,$A5,Данные!$AD$5:$AD$216,1)) -> 2878288.9 | H5: =IF(OR(E5<=0,C5=0,D5=0),0,(E5-F5)/E5*100) -> 11.134573 | I5: =IF(D5=0,0,(SUMIFS(Данные!$M$5:$M$216,Данные!$B$5:$B$216,$A5,Данные!$C$5:$C$216,"M",Данные!$AF$5:$AF$216,INT((D5+1)/2))+SUMIFS(Данные!$M$5:$M$216,Данные!$B$5:$B$216,$A5,Данные!$C$5:$C$216,"M",Данные!$AF$5:$AF$216,INT(D5/2)+1))/2) -> 2952351.9 | J5: =IF(C5=0,0,(SUMIFS(Данные!$M$5:$M$216,Данные!$B$5:$B$216,$A5,Данные!$C$5:$C$216,"F",Данные!$AF$5:$AF$216,INT((C5+1)/2))+SUMIFS(Данные!$M$5:$M$216,Данные!$B$5:$B$216,$A5,Данные!$C$5:$C$216,"F",Данные!$AF$5:$AF$216,INT(C5/2)+1))/2) -> 2619082.9 | K5: =IF(OR(I5<=0,C5=0,D5=0),0,(I5-J5)/I5*100) -> 11.288253 | L5: =IF(D5=0,0,AVERAGEIFS(Данные!$L$5:$L$216,Данные!$B$5:$B$216,$A5,Данные!$C$5:$C$216,"M")) -> 322494.36 | M5: =IF(C5=0,0,AVERAGEIFS(Данные!$L$5:$L$216,Данные!$B$5:$B$216,$A5,Данные!$C$5:$C$216,"F")) -> 277905.99 | N5: =IF(OR(L5<=0,C5=0,D5=0),0,(L5-M5)/L5*100) -> 13.826094 | O5: =IF(D5=0,0,AVERAGEIFS(Данные!$K$5:$K$216,Данные!$B$5:$B$216,$A5,Данные!$C$5:$C$216,"M")) -> 2665033.2 | P5: =IF(C5=0,0,AVERAGEIFS(Данные!$K$5:$K$216,Данные!$B$5:$B$216,$A5,Данные!$C$5:$C$216,"F")) -> 2376973.2 | Q5: =IF(OR(O5<=0,C5=0,D5=0),0,(O5-P5)/O5*100) -> 10.808873 | R5: =IF(B5<2,0,SUMPRODUCT((Данные!$B$5:$B$216=$A5)*Данные!$G$5:$G$216*Данные!$G$5:$G$216)/B5-(SUMIFS(Данные!$G$5:$G$216,Данные!$B$5:$B$216,$A5)/B5)^2) -> 2.0552686 | S5: =IF(B5<2,0,SUMPRODUCT((Данные!$B$5:$B$216=$A5)*Данные!$F$5:$F$216*Данные!$F$5:$F$216)/B5-(SUMIFS(Данные!$F$5:$F$216,Данные!$B$5:$B$216,$A5)/B5)^2) -> 7.5030785 | T5: =IF(AND(B5>=4,R5>0.000000001,S5>0.000000001),1,0) -> 1 | U5: =IF(OR(T5=0,ABS(BK5)<0.000000001),0,((BH5-BB5*BD5/B5)*(BF5-BC5^2/B5)-(BI5-BC5*BD5/B5)*(BG5-BB5*BC5/B5))/BK5) -> 341415.34 | V5: =IF(OR(T5=0,ABS(BK5)<0.000000001),0,((BI5-BC5*BD5/B5)*(BE5-BB5^2/B5)-(BH5-BB5*BD5/B5)*(BG5-BB5*BC5/B5))/BK5) -> 27157.182 | W5: =IF(OR(T5=0,ABS(BK5)<0.000000001,(BJ5-BD5^2/B5)<0.000000001),"",(U5*(BH5-BB5*BD5/B5)+V5*(BI5-BC5*BD5/B5))/(BJ5-BD5^2/B5)) -> 0.88827241 | X5: =IF(H5>=0,MAX(0,MIN(IF(OR(T5=0,E5<=0),0,(U5*(IF(D5=0,0,AVERAGEIFS(Данные!$G$5:$G$216,Данные!$B$5:$B$216,$A5,Данные!$C$5:$C$216,"M"))-IF(C5=0,0,AVERAGEIFS(Данные!$G$5:$G$216,Данные!$B$5:$B$216,$A5,Данные!$C$5:$C$216,"F")))+V5*(IF(D5=0,0,AVERAGEIFS(Данные!$F$5:$F$216,Данные!$B$5:$B$216,$A5,Данные!$C$5:$C$216,"M"))-IF(C5=0,0,AVERAGEIFS(Данные!$F$5:$F$216,Данные!$B$5:$B$216,$A5,Данные!$C$5:$C$216,"F"))))/E5*100),H5)),MIN(0,MAX(IF(OR(T5=0,E5<=0),0,(U5*(IF(D5=0,0,AVERAGEIFS(Данные!$G$5:$G$216,Данные!$B$5:$B$216,$A5,Данные!$C$5:$C$216,"M"))-IF(C5=0,0,AVERAGEIFS(Данные!$G$5:$G$216,Данные!$B$5:$B$216,$A5,Данные!$C$5:$C$216,"F")))+V5*(IF(D5=0,0,AVERAGEIFS(Данные!$F$5:$F$216,Данные!$B$5:$B$216,$A5,Данные!$C$5:$C$216,"M"))-IF(C5=0,0,AVERAGEIFS(Данные!$F$5:$F$216,Данные!$B$5:$B$216,$A5,Данные!$C$5:$C$216,"F"))))/E5*100),H5))) -> 2.0545466 | Y5: =H5-X5 -> 9.0800263 | Z5: =IF(AND(H5>=0,Y5>threshold_pct),1,0) -> 1 | AA5: =IF(Z5=0,0,SUMIFS(Данные!$Q$5:$Q$216,Данные!$B$5:$B$216,$A5)) -> 3894152.5 | AB5: =IF(Z5=0,0,(Y5-threshold_pct)/100*E5*C5) -> 1462703 | AC5: =SUMIFS(Данные!$T$5:$T$216,Данные!$B$5:$B$216,$A5) -> 1397147.9 | AD5: =SUMIFS(Данные!$U$5:$U$216,Данные!$B$5:$B$216,$A5) -> 419144.37 | AE5: =AC5+AD5 -> 1816292.3 | AF5: =SUMIFS(Данные!$P$5:$P$216,Данные!$B$5:$B$216,$A5) -> 8 | AG5: =IF(E5<=0,0,(E5-(IF(C5=0,0,AVERAGEIFS(Данные!$M$5:$M$216,Данные!$B$5:$B$216,$A5,Данные!$C$5:$C$216,"F"))+IF(C5=0,0,SUMIFS(Данные!$S$5:$S$216,Данные!$B$5:$B$216,$A5,Данные!$C$5:$C$216,"F")/C5)))/E5*100-X5) -> 5 | AH5: =IF(AND(H5>=0,Y5>0),1,0) -> 1 | AI5: =IF(AH5=0,0,SUMIFS(Данные!$X$5:$X$216,Данные!$B$5:$B$216,$A5)) -> 3894152.5 | AJ5: =IF(AH5=0,0,Y5/100*E5*C5) -> 3255219.5 | AK5: =SUMIFS(Данные!$AA$5:$AA$216,Данные!$B$5:$B$216,$A5) -> 3109327.9 | AL5: =SUMIFS(Данные!$AB$5:$AB$216,Данные!$B$5:$B$216,$A5) -> 932798.37 | AM5: =AK5+AL5 -> 4042126.3 | AN5: =SUMIFS(Данные!$W$5:$W$216,Данные!$B$5:$B$216,$A5) -> 8 | AO5: =IF(E5<=0,0,(E5-(IF(C5=0,0,AVERAGEIFS(Данные!$M$5:$M$216,Данные!$B$5:$B$216,$A5,Данные!$C$5:$C$216,"F"))+IF(C5=0,0,SUMIFS(Данные!$Z$5:$Z$216,Данные!$B$5:$B$216,$A5,Данные!$C$5:$C$216,"F")/C5)))/E5*100-X5) -> -3.5527137e-15 | AP5: =IF(OR(B5<10,C5<3,D5<3),1,0) -> 0 | AQ5: =IF(H5<0,1,0) -> 0 | BA5: =B5 -> 44 | BB5: =SUMIFS(Данные!$G$5:$G$216,Данные!$B$5:$B$216,$A5) -> 401 | BC5: =SUMIFS(Данные!$F$5:$F$216,Данные!$B$5:$B$216,$A5) -> 305 | BD5: =SUMIFS(Данные!$M$5:$M$216,Данные!$B$5:$B$216,$A5) -> 1.2745943e+08 | BE5: =SUMPRODUCT((Данные!$B$5:$B$216=$A5)*Данные!$G$5:$G$216*Данные!$G$5:$G$216) -> 3745 | BF5: =SUMPRODUCT((Данные!$B$5:$B$216=$A5)*Данные!$F$5:$F$216*Данные!$F$5:$F$216) -> 2444.34 | BG5: =SUMPRODUCT((Данные!$B$5:$B$216=$A5)*Данные!$G$5:$G$216*Данные!$F$5:$F$216) -> 2917.1 | BH5: =SUMPRODUCT((Данные!$B$5:$B$216=$A5)*Данные!$G$5:$G$216*Данные!$M$5:$M$216) -> 1.1962262e+09 | BI5: =SUMPRODUCT((Данные!$B$5:$B$216=$A5)*Данные!$F$5:$F$216*Данные!$M$5:$M$216) -> 9.394156e+08 | BJ5: =SUMPRODUCT((Данные!$B$5:$B$216=$A5)*Данные!$M$5:$M$216*Данные!$M$5:$M$216) -> 384235517800626 | BK5: =IF(T5=0,0,((BE5-BB5^2/B5)*(BF5-BC5^2/B5)-(BG5-BB5*BC5/B5)^2)) -> 10964.746
A6: Операции | B6: =COUNTIF(Данные!$B$5:$B$216,$A6) -> 38 | C6: =COUNTIFS(Данные!$B$5:$B$216,$A6,Данные!$C$5:$C$216,"F") -> 19 | D6: =COUNTIFS(Данные!$B$5:$B$216,$A6,Данные!$C$5:$C$216,"M") -> 19 | E6: =IF(D6=0,0,AVERAGEIFS(Данные!$M$5:$M$216,Данные!$B$5:$B$216,$A6,Данные!$C$5:$C$216,"M")) -> 2314946.4 | F6: =IF(C6=0,0,AVERAGEIFS(Данные!$M$5:$M$216,Данные!$B$5:$B$216,$A6,Данные!$C$5:$C$216,"F")) -> 2050219.7 | G6: =IF(B6=0,0,SUMIFS(Данные!$O$5:$O$216,Данные!$B$5:$B$216,$A6,Данные!$AD$5:$AD$216,1)) -> 2090862.2 | H6: =IF(OR(E6<=0,C6=0,D6=0),0,(E6-F6)/E6*100) -> 11.435542 | I6: =IF(D6=0,0,(SUMIFS(Данные!$M$5:$M$216,Данные!$B$5:$B$216,$A6,Данные!$C$5:$C$216,"M",Данные!$AF$5:$AF$216,INT((D6+1)/2))+SUMIFS(Данные!$M$5:$M$216,Данные!$B$5:$B$216,$A6,Данные!$C$5:$C$216,"M",Данные!$AF$5:$AF$216,INT(D6/2)+1))/2) -> 2280181.3 | J6: =IF(C6=0,0,(SUMIFS(Данные!$M$5:$M$216,Данные!$B$5:$B$216,$A6,Данные!$C$5:$C$216,"F",Данные!$AF$5:$AF$216,INT((C6+1)/2))+SUMIFS(Данные!$M$5:$M$216,Данные!$B$5:$B$216,$A6,Данные!$C$5:$C$216,"F",Данные!$AF$5:$AF$216,INT(C6/2)+1))/2) -> 1845702.8 | K6: =IF(OR(I6<=0,C6=0,D6=0),0,(I6-J6)/I6*100) -> 19.054559 | L6: =IF(D6=0,0,AVERAGEIFS(Данные!$L$5:$L$216,Данные!$B$5:$B$216,$A6,Данные!$C$5:$C$216,"M")) -> 169048.64 | M6: =IF(C6=0,0,AVERAGEIFS(Данные!$L$5:$L$216,Данные!$B$5:$B$216,$A6,Данные!$C$5:$C$216,"F")) -> 148476.9 | N6: =IF(OR(L6<=0,C6=0,D6=0),0,(L6-M6)/L6*100) -> 12.169123 | O6: =IF(D6=0,0,AVERAGEIFS(Данные!$K$5:$K$216,Данные!$B$5:$B$216,$A6,Данные!$C$5:$C$216,"M")) -> 2145897.7 | P6: =IF(C6=0,0,AVERAGEIFS(Данные!$K$5:$K$216,Данные!$B$5:$B$216,$A6,Данные!$C$5:$C$216,"F")) -> 1901742.8 | Q6: =IF(OR(O6<=0,C6=0,D6=0),0,(O6-P6)/O6*100) -> 11.377752 | R6: =IF(B6<2,0,SUMPRODUCT((Данные!$B$5:$B$216=$A6)*Данные!$G$5:$G$216*Данные!$G$5:$G$216)/B6-(SUMIFS(Данные!$G$5:$G$216,Данные!$B$5:$B$216,$A6)/B6)^2) -> 2.1724377 | S6: =IF(B6<2,0,SUMPRODUCT((Данные!$B$5:$B$216=$A6)*Данные!$F$5:$F$216*Данные!$F$5:$F$216)/B6-(SUMIFS(Данные!$F$5:$F$216,Данные!$B$5:$B$216,$A6)/B6)^2) -> 5.962687 | T6: =IF(AND(B6>=4,R6>0.000000001,S6>0.000000001),1,0) -> 1 | U6: =IF(OR(T6=0,ABS(BK6)<0.000000001),0,((BH6-BB6*BD6/B6)*(BF6-BC6^2/B6)-(BI6-BC6*BD6/B6)*(BG6-BB6*BC6/B6))/BK6) -> 286999.3 | V6: =IF(OR(T6=0,ABS(BK6)<0.000000001),0,((BI6-BC6*BD6/B6)*(BE6-BB6^2/B6)-(BH6-BB6*BD6/B6)*(BG6-BB6*BC6/B6))/BK6) -> 17751.043 | W6: =IF(OR(T6=0,ABS(BK6)<0.000000001,(BJ6-BD6^2/B6)<0.000000001),"",(U6*(BH6-BB6*BD6/B6)+V6*(BI6-BC6*BD6/B6))/(BJ6-BD6^2/B6)) -> 0.94277342 | X6: =IF(H6>=0,MAX(0,MIN(IF(OR(T6=0,E6<=0),0,(U6*(IF(D6=0,0,AVERAGEIFS(Данные!$G$5:$G$216,Данные!$B$5:$B$216,$A6,Данные!$C$5:$C$216,"M"))-IF(C6=0,0,AVERAGEIFS(Данные!$G$5:$G$216,Данные!$B$5:$B$216,$A6,Данные!$C$5:$C$216,"F")))+V6*(IF(D6=0,0,AVERAGEIFS(Данные!$F$5:$F$216,Данные!$B$5:$B$216,$A6,Данные!$C$5:$C$216,"M"))-IF(C6=0,0,AVERAGEIFS(Данные!$F$5:$F$216,Данные!$B$5:$B$216,$A6,Данные!$C$5:$C$216,"F"))))/E6*100),H6)),MIN(0,MAX(IF(OR(T6=0,E6<=0),0,(U6*(IF(D6=0,0,AVERAGEIFS(Данные!$G$5:$G$216,Данные!$B$5:$B$216,$A6,Данные!$C$5:$C$216,"M"))-IF(C6=0,0,AVERAGEIFS(Данные!$G$5:$G$216,Данные!$B$5:$B$216,$A6,Данные!$C$5:$C$216,"F")))+V6*(IF(D6=0,0,AVERAGEIFS(Данные!$F$5:$F$216,Данные!$B$5:$B$216,$A6,Данные!$C$5:$C$216,"M"))-IF(C6=0,0,AVERAGEIFS(Данные!$F$5:$F$216,Данные!$B$5:$B$216,$A6,Данные!$C$5:$C$216,"F"))))/E6*100),H6))) -> 9.9597147 | Y6: =H6-X6 -> 1.4758271 | Z6: =IF(AND(H6>=0,Y6>threshold_pct),1,0) -> 0 | AA6: =IF(Z6=0,0,SUMIFS(Данные!$Q$5:$Q$216,Данные!$B$5:$B$216,$A6)) -> 0 | AB6: =IF(Z6=0,0,(Y6-threshold_pct)/100*E6*C6) -> 0 | AC6: =SUMIFS(Данные!$T$5:$T$216,Данные!$B$5:$B$216,$A6) -> 0 | AD6: =SUMIFS(Данные!$U$5:$U$216,Данные!$B$5:$B$216,$A6) -> 0 | AE6: =AC6+AD6 -> 0 | AF6: =SUMIFS(Данные!$P$5:$P$216,Данные!$B$5:$B$216,$A6) -> 0 | AG6: =IF(E6<=0,0,(E6-(IF(C6=0,0,AVERAGEIFS(Данные!$M$5:$M$216,Данные!$B$5:$B$216,$A6,Данные!$C$5:$C$216,"F"))+IF(C6=0,0,SUMIFS(Данные!$S$5:$S$216,Данные!$B$5:$B$216,$A6,Данные!$C$5:$C$216,"F")/C6)))/E6*100-X6) -> 1.4758271 | AH6: =IF(AND(H6>=0,Y6>0),1,0) -> 1 | AI6: =IF(AH6=0,0,SUMIFS(Данные!$X$5:$X$216,Данные!$B$5:$B$216,$A6)) -> 3788948.9 | AJ6: =IF(AH6=0,0,Y6/100*E6*C6) -> 649127.49 | AK6: =SUMIFS(Данные!$AA$5:$AA$216,Данные!$B$5:$B$216,$A6) -> 649127.49 | AL6: =SUMIFS(Данные!$AB$5:$AB$216,Данные!$B$5:$B$216,$A6) -> 194738.25 | AM6: =AK6+AL6 -> 843865.74 | AN6: =SUMIFS(Данные!$W$5:$W$216,Данные!$B$5:$B$216,$A6) -> 12 | AO6: =IF(E6<=0,0,(E6-(IF(C6=0,0,AVERAGEIFS(Данные!$M$5:$M$216,Данные!$B$5:$B$216,$A6,Данные!$C$5:$C$216,"F"))+IF(C6=0,0,SUMIFS(Данные!$Z$5:$Z$216,Данные!$B$5:$B$216,$A6,Данные!$C$5:$C$216,"F")/C6)))/E6*100-X6) -> 0 | AP6: =IF(OR(B6<10,C6<3,D6<3),1,0) -> 0 | AQ6: =IF(H6<0,1,0) -> 0 | BA6: =B6 -> 38 | BB6: =SUMIFS(Данные!$G$5:$G$216,Данные!$B$5:$B$216,$A6) -> 253 | BC6: =SUMIFS(Данные!$F$5:$F$216,Данные!$B$5:$B$216,$A6) -> 214 | BD6: =SUMIFS(Данные!$M$5:$M$216,Данные!$B$5:$B$216,$A6) -> 82938156 | BE6: =SUMPRODUCT((Данные!$B$5:$B$216=$A6)*Данные!$G$5:$G$216*Данные!$G$5:$G$216) -> 1767 | BF6: =SUMPRODUCT((Данные!$B$5:$B$216=$A6)*Данные!$F$5:$F$216*Данные!$F$5:$F$216) -> 1431.74 | BG6: =SUMPRODUCT((Данные!$B$5:$B$216=$A6)*Данные!$G$5:$G$216*Данные!$F$5:$F$216) -> 1527.5 | BH6: =SUMPRODUCT((Данные!$B$5:$B$216=$A6)*Данные!$G$5:$G$216*Данные!$M$5:$M$216) -> 5.7770928e+08 | BI6: =SUMPRODUCT((Данные!$B$5:$B$216=$A6)*Данные!$F$5:$F$216*Данные!$M$5:$M$216) -> 5.0057269e+08 | BJ6: =SUMPRODUCT((Данные!$B$5:$B$216=$A6)*Данные!$M$5:$M$216*Данные!$M$5:$M$216) -> 1.8941768e+14 | BK6: =IF(T6=0,0,((BE6-BB6^2/B6)*(BF6-BC6^2/B6)-(BG6-BB6*BC6/B6)^2)) -> 8155.4968
A7: Юристы | B7: =COUNTIF(Данные!$B$5:$B$216,$A7) -> 8 | C7: =COUNTIFS(Данные!$B$5:$B$216,$A7,Данные!$C$5:$C$216,"F") -> 3 | D7: =COUNTIFS(Данные!$B$5:$B$216,$A7,Данные!$C$5:$C$216,"M") -> 5 | E7: =IF(D7=0,0,AVERAGEIFS(Данные!$M$5:$M$216,Данные!$B$5:$B$216,$A7,Данные!$C$5:$C$216,"M")) -> 3717394.6 | F7: =IF(C7=0,0,AVERAGEIFS(Данные!$M$5:$M$216,Данные!$B$5:$B$216,$A7,Данные!$C$5:$C$216,"F")) -> 3143268.3 | G7: =IF(B7=0,0,SUMIFS(Данные!$O$5:$O$216,Данные!$B$5:$B$216,$A7,Данные!$AD$5:$AD$216,1)) -> 3304474.8 | H7: =IF(OR(E7<=0,C7=0,D7=0),0,(E7-F7)/E7*100) -> 15.444319 | I7: =IF(D7=0,0,(SUMIFS(Данные!$M$5:$M$216,Данные!$B$5:$B$216,$A7,Данные!$C$5:$C$216,"M",Данные!$AF$5:$AF$216,INT((D7+1)/2))+SUMIFS(Данные!$M$5:$M$216,Данные!$B$5:$B$216,$A7,Данные!$C$5:$C$216,"M",Данные!$AF$5:$AF$216,INT(D7/2)+1))/2) -> 3806945 | J7: =IF(C7=0,0,(SUMIFS(Данные!$M$5:$M$216,Данные!$B$5:$B$216,$A7,Данные!$C$5:$C$216,"F",Данные!$AF$5:$AF$216,INT((C7+1)/2))+SUMIFS(Данные!$M$5:$M$216,Данные!$B$5:$B$216,$A7,Данные!$C$5:$C$216,"F",Данные!$AF$5:$AF$216,INT(C7/2)+1))/2) -> 3167240 | K7: =IF(OR(I7<=0,C7=0,D7=0),0,(I7-J7)/I7*100) -> 16.80363 | L7: =IF(D7=0,0,AVERAGEIFS(Данные!$L$5:$L$216,Данные!$B$5:$B$216,$A7,Данные!$C$5:$C$216,"M")) -> 470862.29 | M7: =IF(C7=0,0,AVERAGEIFS(Данные!$L$5:$L$216,Данные!$B$5:$B$216,$A7,Данные!$C$5:$C$216,"F")) -> 447365.64 | N7: =IF(OR(L7<=0,C7=0,D7=0),0,(L7-M7)/L7*100) -> 4.9901312 | O7: =IF(D7=0,0,AVERAGEIFS(Данные!$K$5:$K$216,Данные!$B$5:$B$216,$A7,Данные!$C$5:$C$216,"M")) -> 3246532.3 | P7: =IF(C7=0,0,AVERAGEIFS(Данные!$K$5:$K$216,Данные!$B$5:$B$216,$A7,Данные!$C$5:$C$216,"F")) -> 2695902.7 | Q7: =IF(OR(O7<=0,C7=0,D7=0),0,(O7-P7)/O7*100) -> 16.960547 | R7: =IF(B7<2,0,SUMPRODUCT((Данные!$B$5:$B$216=$A7)*Данные!$G$5:$G$216*Данные!$G$5:$G$216)/B7-(SUMIFS(Данные!$G$5:$G$216,Данные!$B$5:$B$216,$A7)/B7)^2) -> 0.859375 | S7: =IF(B7<2,0,SUMPRODUCT((Данные!$B$5:$B$216=$A7)*Данные!$F$5:$F$216*Данные!$F$5:$F$216)/B7-(SUMIFS(Данные!$F$5:$F$216,Данные!$B$5:$B$216,$A7)/B7)^2) -> 5.7773438 | T7: =IF(AND(B7>=4,R7>0.000000001,S7>0.000000001),1,0) -> 1 | U7: =IF(OR(T7=0,ABS(BK7)<0.000000001),0,((BH7-BB7*BD7/B7)*(BF7-BC7^2/B7)-(BI7-BC7*BD7/B7)*(BG7-BB7*BC7/B7))/BK7) -> 489641.85 | V7: =IF(OR(T7=0,ABS(BK7)<0.000000001),0,((BI7-BC7*BD7/B7)*(BE7-BB7^2/B7)-(BH7-BB7*BD7/B7)*(BG7-BB7*BC7/B7))/BK7) -> 38882.218 | W7: =IF(OR(T7=0,ABS(BK7)<0.000000001,(BJ7-BD7^2/B7)<0.000000001),"",(U7*(BH7-BB7*BD7/B7)+V7*(BI7-BC7*BD7/B7))/(BJ7-BD7^2/B7)) -> 0.9043136 | X7: =IF(H7>=0,MAX(0,MIN(IF(OR(T7=0,E7<=0),0,(U7*(IF(D7=0,0,AVERAGEIFS(Данные!$G$5:$G$216,Данные!$B$5:$B$216,$A7,Данные!$C$5:$C$216,"M"))-IF(C7=0,0,AVERAGEIFS(Данные!$G$5:$G$216,Данные!$B$5:$B$216,$A7,Данные!$C$5:$C$216,"F")))+V7*(IF(D7=0,0,AVERAGEIFS(Данные!$F$5:$F$216,Данные!$B$5:$B$216,$A7,Данные!$C$5:$C$216,"M"))-IF(C7=0,0,AVERAGEIFS(Данные!$F$5:$F$216,Данные!$B$5:$B$216,$A7,Данные!$C$5:$C$216,"F"))))/E7*100),H7)),MIN(0,MAX(IF(OR(T7=0,E7<=0),0,(U7*(IF(D7=0,0,AVERAGEIFS(Данные!$G$5:$G$216,Данные!$B$5:$B$216,$A7,Данные!$C$5:$C$216,"M"))-IF(C7=0,0,AVERAGEIFS(Данные!$G$5:$G$216,Данные!$B$5:$B$216,$A7,Данные!$C$5:$C$216,"F")))+V7*(IF(D7=0,0,AVERAGEIFS(Данные!$F$5:$F$216,Данные!$B$5:$B$216,$A7,Данные!$C$5:$C$216,"M"))-IF(C7=0,0,AVERAGEIFS(Данные!$F$5:$F$216,Данные!$B$5:$B$216,$A7,Данные!$C$5:$C$216,"F"))))/E7*100),H7))) -> 8.8851973 | Y7: =H7-X7 -> 6.5591221 | Z7: =IF(AND(H7>=0,Y7>threshold_pct),1,0) -> 1 | AA7: =IF(Z7=0,0,SUMIFS(Данные!$Q$5:$Q$216,Данные!$B$5:$B$216,$A7)) -> 483619.49 | AB7: =IF(Z7=0,0,(Y7-threshold_pct)/100*E7*C7) -> 173876.16 | AC7: =SUMIFS(Данные!$T$5:$T$216,Данные!$B$5:$B$216,$A7) -> 173876.16 | AD7: =SUMIFS(Данные!$U$5:$U$216,Данные!$B$5:$B$216,$A7) -> 52162.848 | AE7: =AC7+AD7 -> 226039.01 | AF7: =SUMIFS(Данные!$P$5:$P$216,Данные!$B$5:$B$216,$A7) -> 3 | AG7: =IF(E7<=0,0,(E7-(IF(C7=0,0,AVERAGEIFS(Данные!$M$5:$M$216,Данные!$B$5:$B$216,$A7,Данные!$C$5:$C$216,"F"))+IF(C7=0,0,SUMIFS(Данные!$S$5:$S$216,Данные!$B$5:$B$216,$A7,Данные!$C$5:$C$216,"F")/C7)))/E7*100-X7) -> 5 | AH7: =IF(AND(H7>=0,Y7>0),1,0) -> 1 | AI7: =IF(AH7=0,0,SUMIFS(Данные!$X$5:$X$216,Данные!$B$5:$B$216,$A7)) -> 483619.49 | AJ7: =IF(AH7=0,0,Y7/100*E7*C7) -> 731485.35 | AK7: =SUMIFS(Данные!$AA$5:$AA$216,Данные!$B$5:$B$216,$A7) -> 731485.35 | AL7: =SUMIFS(Данные!$AB$5:$AB$216,Данные!$B$5:$B$216,$A7) -> 207625.53 | AM7: =AK7+AL7 -> 939110.88 | AN7: =SUMIFS(Данные!$W$5:$W$216,Данные!$B$5:$B$216,$A7) -> 3 | AO7: =IF(E7<=0,0,(E7-(IF(C7=0,0,AVERAGEIFS(Данные!$M$5:$M$216,Данные!$B$5:$B$216,$A7,Данные!$C$5:$C$216,"F"))+IF(C7=0,0,SUMIFS(Данные!$Z$5:$Z$216,Данные!$B$5:$B$216,$A7,Данные!$C$5:$C$216,"F")/C7)))/E7*100-X7) -> 0 | AP7: =IF(OR(B7<10,C7<3,D7<3),1,0) -> 1 | AQ7: =IF(H7<0,1,0) -> 0 | BA7: =B7 -> 8 | BB7: =SUMIFS(Данные!$G$5:$G$216,Данные!$B$5:$B$216,$A7) -> 81 | BC7: =SUMIFS(Данные!$F$5:$F$216,Данные!$B$5:$B$216,$A7) -> 45.1 | BD7: =SUMIFS(Данные!$M$5:$M$216,Данные!$B$5:$B$216,$A7) -> 28016778 | BE7: =SUMPRODUCT((Данные!$B$5:$B$216=$A7)*Данные!$G$5:$G$216*Данные!$G$5:$G$216) -> 827 | BF7: =SUMPRODUCT((Данные!$B$5:$B$216=$A7)*Данные!$F$5:$F$216*Данные!$F$5:$F$216) -> 300.47 | BG7: =SUMPRODUCT((Данные!$B$5:$B$216=$A7)*Данные!$G$5:$G$216*Данные!$F$5:$F$216) -> 465.7 | BH7: =SUMPRODUCT((Данные!$B$5:$B$216=$A7)*Данные!$G$5:$G$216*Данные!$M$5:$M$216) -> 2.8738853e+08 | BI7: =SUMPRODUCT((Данные!$B$5:$B$216=$A7)*Данные!$F$5:$F$216*Данные!$M$5:$M$216) -> 1.6417905e+08 | BJ7: =SUMPRODUCT((Данные!$B$5:$B$216=$A7)*Данные!$M$5:$M$216*Данные!$M$5:$M$216) -> 1.0039901e+14 | BK7: =IF(T7=0,0,((BE7-BB7^2/B7)*(BF7-BC7^2/B7)-(BG7-BB7*BC7/B7)^2)) -> 235.625
A8: Маркетинг | B8: =COUNTIF(Данные!$B$5:$B$216,$A8) -> 26 | C8: =COUNTIFS(Данные!$B$5:$B$216,$A8,Данные!$C$5:$C$216,"F") -> 12 | D8: =COUNTIFS(Данные!$B$5:$B$216,$A8,Данные!$C$5:$C$216,"M") -> 14 | E8: =IF(D8=0,0,AVERAGEIFS(Данные!$M$5:$M$216,Данные!$B$5:$B$216,$A8,Данные!$C$5:$C$216,"M")) -> 2735830.8 | F8: =IF(C8=0,0,AVERAGEIFS(Данные!$M$5:$M$216,Данные!$B$5:$B$216,$A8,Данные!$C$5:$C$216,"F")) -> 3108957.9 | G8: =IF(B8=0,0,SUMIFS(Данные!$O$5:$O$216,Данные!$B$5:$B$216,$A8,Данные!$AD$5:$AD$216,1)) -> 3024133.7 | H8: =IF(OR(E8<=0,C8=0,D8=0),0,(E8-F8)/E8*100) -> -13.638532 | I8: =IF(D8=0,0,(SUMIFS(Данные!$M$5:$M$216,Данные!$B$5:$B$216,$A8,Данные!$C$5:$C$216,"M",Данные!$AF$5:$AF$216,INT((D8+1)/2))+SUMIFS(Данные!$M$5:$M$216,Данные!$B$5:$B$216,$A8,Данные!$C$5:$C$216,"M",Данные!$AF$5:$AF$216,INT(D8/2)+1))/2) -> 2734253.1 | J8: =IF(C8=0,0,(SUMIFS(Данные!$M$5:$M$216,Данные!$B$5:$B$216,$A8,Данные!$C$5:$C$216,"F",Данные!$AF$5:$AF$216,INT((C8+1)/2))+SUMIFS(Данные!$M$5:$M$216,Данные!$B$5:$B$216,$A8,Данные!$C$5:$C$216,"F",Данные!$AF$5:$AF$216,INT(C8/2)+1))/2) -> 3137735.2 | K8: =IF(OR(I8<=0,C8=0,D8=0),0,(I8-J8)/I8*100) -> -14.756577 | L8: =IF(D8=0,0,AVERAGEIFS(Данные!$L$5:$L$216,Данные!$B$5:$B$216,$A8,Данные!$C$5:$C$216,"M")) -> 257825.18 | M8: =IF(C8=0,0,AVERAGEIFS(Данные!$L$5:$L$216,Данные!$B$5:$B$216,$A8,Данные!$C$5:$C$216,"F")) -> 280309.48 | N8: =IF(OR(L8<=0,C8=0,D8=0),0,(L8-M8)/L8*100) -> -8.7207554 | O8: =IF(D8=0,0,AVERAGEIFS(Данные!$K$5:$K$216,Данные!$B$5:$B$216,$A8,Данные!$C$5:$C$216,"M")) -> 2478005.6 | P8: =IF(C8=0,0,AVERAGEIFS(Данные!$K$5:$K$216,Данные!$B$5:$B$216,$A8,Данные!$C$5:$C$216,"F")) -> 2828648.4 | Q8: =IF(OR(O8<=0,C8=0,D8=0),0,(O8-P8)/O8*100) -> -14.150204 | R8: =IF(B8<2,0,SUMPRODUCT((Данные!$B$5:$B$216=$A8)*Данные!$G$5:$G$216*Данные!$G$5:$G$216)/B8-(SUMIFS(Данные!$G$5:$G$216,Данные!$B$5:$B$216,$A8)/B8)^2) -> 1.7056213 | S8: =IF(B8<2,0,SUMPRODUCT((Данные!$B$5:$B$216=$A8)*Данные!$F$5:$F$216*Данные!$F$5:$F$216)/B8-(SUMIFS(Данные!$F$5:$F$216,Данные!$B$5:$B$216,$A8)/B8)^2) -> 7.3016716 | T8: =IF(AND(B8>=4,R8>0.000000001,S8>0.000000001),1,0) -> 1 | U8: =IF(OR(T8=0,ABS(BK8)<0.000000001),0,((BH8-BB8*BD8/B8)*(BF8-BC8^2/B8)-(BI8-BC8*BD8/B8)*(BG8-BB8*BC8/B8))/BK8) -> 266957.08 | V8: =IF(OR(T8=0,ABS(BK8)<0.000000001),0,((BI8-BC8*BD8/B8)*(BE8-BB8^2/B8)-(BH8-BB8*BD8/B8)*(BG8-BB8*BC8/B8))/BK8) -> 34355.153 | W8: =IF(OR(T8=0,ABS(BK8)<0.000000001,(BJ8-BD8^2/B8)<0.000000001),"",(U8*(BH8-BB8*BD8/B8)+V8*(BI8-BC8*BD8/B8))/(BJ8-BD8^2/B8)) -> 0.87479522 | X8: =IF(H8>=0,MAX(0,MIN(IF(OR(T8=0,E8<=0),0,(U8*(IF(D8=0,0,AVERAGEIFS(Данные!$G$5:$G$216,Данные!$B$5:$B$216,$A8,Данные!$C$5:$C$216,"M"))-IF(C8=0,0,AVERAGEIFS(Данные!$G$5:$G$216,Данные!$B$5:$B$216,$A8,Данные!$C$5:$C$216,"F")))+V8*(IF(D8=0,0,AVERAGEIFS(Данные!$F$5:$F$216,Данные!$B$5:$B$216,$A8,Данные!$C$5:$C$216,"M"))-IF(C8=0,0,AVERAGEIFS(Данные!$F$5:$F$216,Данные!$B$5:$B$216,$A8,Данные!$C$5:$C$216,"F"))))/E8*100),H8)),MIN(0,MAX(IF(OR(T8=0,E8<=0),0,(U8*(IF(D8=0,0,AVERAGEIFS(Данные!$G$5:$G$216,Данные!$B$5:$B$216,$A8,Данные!$C$5:$C$216,"M"))-IF(C8=0,0,AVERAGEIFS(Данные!$G$5:$G$216,Данные!$B$5:$B$216,$A8,Данные!$C$5:$C$216,"F")))+V8*(IF(D8=0,0,AVERAGEIFS(Данные!$F$5:$F$216,Данные!$B$5:$B$216,$A8,Данные!$C$5:$C$216,"M"))-IF(C8=0,0,AVERAGEIFS(Данные!$F$5:$F$216,Данные!$B$5:$B$216,$A8,Данные!$C$5:$C$216,"F"))))/E8*100),H8))) -> -6.3388453 | Y8: =H8-X8 -> -7.2996864 | Z8: =IF(AND(H8>=0,Y8>threshold_pct),1,0) -> 0 | AA8: =IF(Z8=0,0,SUMIFS(Данные!$Q$5:$Q$216,Данные!$B$5:$B$216,$A8)) -> 0 | AB8: =IF(Z8=0,0,(Y8-threshold_pct)/100*E8*C8) -> 0 | AC8: =SUMIFS(Данные!$T$5:$T$216,Данные!$B$5:$B$216,$A8) -> 0 | AD8: =SUMIFS(Данные!$U$5:$U$216,Данные!$B$5:$B$216,$A8) -> 0 | AE8: =AC8+AD8 -> 0 | AF8: =SUMIFS(Данные!$P$5:$P$216,Данные!$B$5:$B$216,$A8) -> 0 | AG8: =IF(E8<=0,0,(E8-(IF(C8=0,0,AVERAGEIFS(Данные!$M$5:$M$216,Данные!$B$5:$B$216,$A8,Данные!$C$5:$C$216,"F"))+IF(C8=0,0,SUMIFS(Данные!$S$5:$S$216,Данные!$B$5:$B$216,$A8,Данные!$C$5:$C$216,"F")/C8)))/E8*100-X8) -> -7.2996864 | AH8: =IF(AND(H8>=0,Y8>0),1,0) -> 0 | AI8: =IF(AH8=0,0,SUMIFS(Данные!$X$5:$X$216,Данные!$B$5:$B$216,$A8)) -> 0 | AJ8: =IF(AH8=0,0,Y8/100*E8*C8) -> 0 | AK8: =SUMIFS(Данные!$AA$5:$AA$216,Данные!$B$5:$B$216,$A8) -> 0 | AL8: =SUMIFS(Данные!$AB$5:$AB$216,Данные!$B$5:$B$216,$A8) -> 0 | AM8: =AK8+AL8 -> 0 | AN8: =SUMIFS(Данные!$W$5:$W$216,Данные!$B$5:$B$216,$A8) -> 0 | AO8: =IF(E8<=0,0,(E8-(IF(C8=0,0,AVERAGEIFS(Данные!$M$5:$M$216,Данные!$B$5:$B$216,$A8,Данные!$C$5:$C$216,"F"))+IF(C8=0,0,SUMIFS(Данные!$Z$5:$Z$216,Данные!$B$5:$B$216,$A8,Данные!$C$5:$C$216,"F")/C8)))/E8*100-X8) -> -7.2996864 | AP8: =IF(OR(B8<10,C8<3,D8<3),1,0) -> 0 | AQ8: =IF(H8<0,1,0) -> 1 | BA8: =B8 -> 26 | BB8: =SUMIFS(Данные!$G$5:$G$216,Данные!$B$5:$B$216,$A8) -> 223 | BC8: =SUMIFS(Данные!$F$5:$F$216,Данные!$B$5:$B$216,$A8) -> 204.3 | BD8: =SUMIFS(Данные!$M$5:$M$216,Данные!$B$5:$B$216,$A8) -> 75609126 | BE8: =SUMPRODUCT((Данные!$B$5:$B$216=$A8)*Данные!$G$5:$G$216*Данные!$G$5:$G$216) -> 1957 | BF8: =SUMPRODUCT((Данные!$B$5:$B$216=$A8)*Данные!$F$5:$F$216*Данные!$F$5:$F$216) -> 1795.17 | BG8: =SUMPRODUCT((Данные!$B$5:$B$216=$A8)*Данные!$G$5:$G$216*Данные!$F$5:$F$216) -> 1821.7 | BH8: =SUMPRODUCT((Данные!$B$5:$B$216=$A8)*Данные!$G$5:$G$216*Данные!$M$5:$M$216) -> 6.6271761e+08 | BI8: =SUMPRODUCT((Данные!$B$5:$B$216=$A8)*Данные!$F$5:$F$216*Данные!$M$5:$M$216) -> 6.1917141e+08 | BJ8: =SUMPRODUCT((Данные!$B$5:$B$216=$A8)*Данные!$M$5:$M$216*Данные!$M$5:$M$216) -> 2.2519936e+14 | BK8: =IF(T8=0,0,((BE8-BB8^2/B8)*(BF8-BC8^2/B8)-(BG8-BB8*BC8/B8)^2)) -> 3597.6615
A9: Производство | B9: =COUNTIF(Данные!$B$5:$B$216,$A9) -> 40 | C9: =COUNTIFS(Данные!$B$5:$B$216,$A9,Данные!$C$5:$C$216,"F") -> 19 | D9: =COUNTIFS(Данные!$B$5:$B$216,$A9,Данные!$C$5:$C$216,"M") -> 21 | E9: =IF(D9=0,0,AVERAGEIFS(Данные!$M$5:$M$216,Данные!$B$5:$B$216,$A9,Данные!$C$5:$C$216,"M")) -> 2171756.1 | F9: =IF(C9=0,0,AVERAGEIFS(Данные!$M$5:$M$216,Данные!$B$5:$B$216,$A9,Данные!$C$5:$C$216,"F")) -> 1832765.1 | G9: =IF(B9=0,0,SUMIFS(Данные!$O$5:$O$216,Данные!$B$5:$B$216,$A9,Данные!$AD$5:$AD$216,1)) -> 1952127.1 | H9: =IF(OR(E9<=0,C9=0,D9=0),0,(E9-F9)/E9*100) -> 15.609074 | I9: =IF(D9=0,0,(SUMIFS(Данные!$M$5:$M$216,Данные!$B$5:$B$216,$A9,Данные!$C$5:$C$216,"M",Данные!$AF$5:$AF$216,INT((D9+1)/2))+SUMIFS(Данные!$M$5:$M$216,Данные!$B$5:$B$216,$A9,Данные!$C$5:$C$216,"M",Данные!$AF$5:$AF$216,INT(D9/2)+1))/2) -> 2165704.2 | J9: =IF(C9=0,0,(SUMIFS(Данные!$M$5:$M$216,Данные!$B$5:$B$216,$A9,Данные!$C$5:$C$216,"F",Данные!$AF$5:$AF$216,INT((C9+1)/2))+SUMIFS(Данные!$M$5:$M$216,Данные!$B$5:$B$216,$A9,Данные!$C$5:$C$216,"F",Данные!$AF$5:$AF$216,INT(C9/2)+1))/2) -> 1726882.9 | K9: =IF(OR(I9<=0,C9=0,D9=0),0,(I9-J9)/I9*100) -> 20.262296 | L9: =IF(D9=0,0,AVERAGEIFS(Данные!$L$5:$L$216,Данные!$B$5:$B$216,$A9,Данные!$C$5:$C$216,"M")) -> 128585.34 | M9: =IF(C9=0,0,AVERAGEIFS(Данные!$L$5:$L$216,Данные!$B$5:$B$216,$A9,Данные!$C$5:$C$216,"F")) -> 101484.2 | N9: =IF(OR(L9<=0,C9=0,D9=0),0,(L9-M9)/L9*100) -> 21.076385 | O9: =IF(D9=0,0,AVERAGEIFS(Данные!$K$5:$K$216,Данные!$B$5:$B$216,$A9,Данные!$C$5:$C$216,"M")) -> 2043170.8 | P9: =IF(C9=0,0,AVERAGEIFS(Данные!$K$5:$K$216,Данные!$B$5:$B$216,$A9,Данные!$C$5:$C$216,"F")) -> 1731280.9 | Q9: =IF(OR(O9<=0,C9=0,D9=0),0,(O9-P9)/O9*100) -> 15.264993 | R9: =IF(B9<2,0,SUMPRODUCT((Данные!$B$5:$B$216=$A9)*Данные!$G$5:$G$216*Данные!$G$5:$G$216)/B9-(SUMIFS(Данные!$G$5:$G$216,Данные!$B$5:$B$216,$A9)/B9)^2) -> 1.5875 | S9: =IF(B9<2,0,SUMPRODUCT((Данные!$B$5:$B$216=$A9)*Данные!$F$5:$F$216*Данные!$F$5:$F$216)/B9-(SUMIFS(Данные!$F$5:$F$216,Данные!$B$5:$B$216,$A9)/B9)^2) -> 19.436244 | T9: =IF(AND(B9>=4,R9>0.000000001,S9>0.000000001),1,0) -> 1 | U9: =IF(OR(T9=0,ABS(BK9)<0.000000001),0,((BH9-BB9*BD9/B9)*(BF9-BC9^2/B9)-(BI9-BC9*BD9/B9)*(BG9-BB9*BC9/B9))/BK9) -> 230251.78 | V9: =IF(OR(T9=0,ABS(BK9)<0.000000001),0,((BI9-BC9*BD9/B9)*(BE9-BB9^2/B9)-(BH9-BB9*BD9/B9)*(BG9-BB9*BC9/B9))/BK9) -> 29115.614 | W9: =IF(OR(T9=0,ABS(BK9)<0.000000001,(BJ9-BD9^2/B9)<0.000000001),"",(U9*(BH9-BB9*BD9/B9)+V9*(BI9-BC9*BD9/B9))/(BJ9-BD9^2/B9)) -> 0.91301294 | X9: =IF(H9>=0,MAX(0,MIN(IF(OR(T9=0,E9<=0),0,(U9*(IF(D9=0,0,AVERAGEIFS(Данные!$G$5:$G$216,Данные!$B$5:$B$216,$A9,Данные!$C$5:$C$216,"M"))-IF(C9=0,0,AVERAGEIFS(Данные!$G$5:$G$216,Данные!$B$5:$B$216,$A9,Данные!$C$5:$C$216,"F")))+V9*(IF(D9=0,0,AVERAGEIFS(Данные!$F$5:$F$216,Данные!$B$5:$B$216,$A9,Данные!$C$5:$C$216,"M"))-IF(C9=0,0,AVERAGEIFS(Данные!$F$5:$F$216,Данные!$B$5:$B$216,$A9,Данные!$C$5:$C$216,"F"))))/E9*100),H9)),MIN(0,MAX(IF(OR(T9=0,E9<=0),0,(U9*(IF(D9=0,0,AVERAGEIFS(Данные!$G$5:$G$216,Данные!$B$5:$B$216,$A9,Данные!$C$5:$C$216,"M"))-IF(C9=0,0,AVERAGEIFS(Данные!$G$5:$G$216,Данные!$B$5:$B$216,$A9,Данные!$C$5:$C$216,"F")))+V9*(IF(D9=0,0,AVERAGEIFS(Данные!$F$5:$F$216,Данные!$B$5:$B$216,$A9,Данные!$C$5:$C$216,"M"))-IF(C9=0,0,AVERAGEIFS(Данные!$F$5:$F$216,Данные!$B$5:$B$216,$A9,Данные!$C$5:$C$216,"F"))))/E9*100),H9))) -> 8.9498184 | Y9: =H9-X9 -> 6.6592552 | Z9: =IF(AND(H9>=0,Y9>threshold_pct),1,0) -> 1 | AA9: =IF(Z9=0,0,SUMIFS(Данные!$Q$5:$Q$216,Данные!$B$5:$B$216,$A9)) -> 4227667.1 | AB9: =IF(Z9=0,0,(Y9-threshold_pct)/100*E9*C9) -> 684664.57 | AC9: =SUMIFS(Данные!$T$5:$T$216,Данные!$B$5:$B$216,$A9) -> 657557.37 | AD9: =SUMIFS(Данные!$U$5:$U$216,Данные!$B$5:$B$216,$A9) -> 197267.21 | AE9: =AC9+AD9 -> 854824.58 | AF9: =SUMIFS(Данные!$P$5:$P$216,Данные!$B$5:$B$216,$A9) -> 12 | AG9: =IF(E9<=0,0,(E9-(IF(C9=0,0,AVERAGEIFS(Данные!$M$5:$M$216,Данные!$B$5:$B$216,$A9,Данные!$C$5:$C$216,"F"))+IF(C9=0,0,SUMIFS(Данные!$S$5:$S$216,Данные!$B$5:$B$216,$A9,Данные!$C$5:$C$216,"F")/C9)))/E9*100-X9) -> 5 | AH9: =IF(AND(H9>=0,Y9>0),1,0) -> 1 | AI9: =IF(AH9=0,0,SUMIFS(Данные!$X$5:$X$216,Данные!$B$5:$B$216,$A9)) -> 4227667.1 | AJ9: =IF(AH9=0,0,Y9/100*E9*C9) -> 2747832.9 | AK9: =SUMIFS(Данные!$AA$5:$AA$216,Данные!$B$5:$B$216,$A9) -> 2639040.8 | AL9: =SUMIFS(Данные!$AB$5:$AB$216,Данные!$B$5:$B$216,$A9) -> 791712.25 | AM9: =AK9+AL9 -> 3430753.1 | AN9: =SUMIFS(Данные!$W$5:$W$216,Данные!$B$5:$B$216,$A9) -> 12 | AO9: =IF(E9<=0,0,(E9-(IF(C9=0,0,AVERAGEIFS(Данные!$M$5:$M$216,Данные!$B$5:$B$216,$A9,Данные!$C$5:$C$216,"F"))+IF(C9=0,0,SUMIFS(Данные!$Z$5:$Z$216,Данные!$B$5:$B$216,$A9,Данные!$C$5:$C$216,"F")/C9)))/E9*100-X9) -> 1.7763568e-15 | AP9: =IF(OR(B9<10,C9<3,D9<3),1,0) -> 0 | AQ9: =IF(H9<0,1,0) -> 0 | BA9: =B9 -> 40 | BB9: =SUMIFS(Данные!$G$5:$G$216,Данные!$B$5:$B$216,$A9) -> 230 | BC9: =SUMIFS(Данные!$F$5:$F$216,Данные!$B$5:$B$216,$A9) -> 411.1 | BD9: =SUMIFS(Данные!$M$5:$M$216,Данные!$B$5:$B$216,$A9) -> 80429415 | BE9: =SUMPRODUCT((Данные!$B$5:$B$216=$A9)*Данные!$G$5:$G$216*Данные!$G$5:$G$216) -> 1386 | BF9: =SUMPRODUCT((Данные!$B$5:$B$216=$A9)*Данные!$F$5:$F$216*Данные!$F$5:$F$216) -> 5002.53 | BG9: =SUMPRODUCT((Данные!$B$5:$B$216=$A9)*Данные!$G$5:$G$216*Данные!$F$5:$F$216) -> 2527 | BH9: =SUMPRODUCT((Данные!$B$5:$B$216=$A9)*Данные!$G$5:$G$216*Данные!$M$5:$M$216) -> 4.8184107e+08 | BI9: =SUMPRODUCT((Данные!$B$5:$B$216=$A9)*Данные!$F$5:$F$216*Данные!$M$5:$M$216) -> 8.8682058e+08 | BJ9: =SUMPRODUCT((Данные!$B$5:$B$216=$A9)*Данные!$M$5:$M$216*Данные!$M$5:$M$216) -> 1.6852764e+14 | BK9: =IF(T9=0,0,((BE9-BB9^2/B9)*(BF9-BC9^2/B9)-(BG9-BB9*BC9/B9)^2)) -> 22741.978
